Workbook

Sheet Janeiro
B2: Janeiro | Z2: Categoria | AA2: Valor gasto
R3: Saldo: | S3: =S10-S18 -> 0 | U3: Gastos do mês por categoria: | Z3: =U5 -> Mercado | AA3: =W5 -> 0
B4: Total de gastos: | F4: =F7+F20+N4 -> 0 | J4: Total de Gastos do Mês: | N4: =SUM(P8:P35) -> 0 | U4: Categoria | V4: Valor esperado | W4: Valor gasto | X4: Porcentagem | Z4: =U6 -> Despesas eventuais | AA4: =W6 -> 0
U5: Mercado | W5: =SUMIF($G$11:$G$18,U5,$H$11:$H$18)+SUMIF($G$24:$G$35,U5,$H$24:$H$35)+SUMIF($N$8:$N$35,U5,$P$8:$P$35) -> 0 | X5: =IF($F$4=0,0,W5/$F$4) -> 0 | Z5: =U7 -> Necessidades | AA5: =W7 -> 0
J6: Gastos do Mês | U6: Despesas eventuais | W6: =SUMIF($G$11:$G$18,U6,$H$11:$H$18)+SUMIF($G$24:$G$35,U6,$H$24:$H$35)+SUMIF($N$8:$N$35,U6,$P$8:$P$35) -> 0 | X6: =IF($F$4=0,0,W6/$F$4) -> 0 | Z6: =U8 -> Roupa | AA6: =W8 -> 0
B7: Total de Fixos: | F7: =SUM(H11:H18) -> 0 | J7: Nome | L7: Data | M7: Tipo | N7: Categoria | P7: Valor | R7: Entradas | U7: Necessidades | W7: =SUMIF($G$11:$G$18,U7,$H$11:$H$18)+SUMIF($G$24:$G$35,U7,$H$24:$H$35)+SUMIF($N$8:$N$35,U7,$P$8:$P$35) -> 0 | X7: =IF($F$4=0,0,W7/$F$4) -> 0 | Z7: =U9 -> Saúde | AA7: =W9 -> 0
R8: Salário | U8: Roupa | W8: =SUMIF($G$11:$G$18,U8,$H$11:$H$18)+SUMIF($G$24:$G$35,U8,$H$24:$H$35)+SUMIF($N$8:$N$35,U8,$P$8:$P$35) -> 0 | X8: =IF($F$4=0,0,W8/$F$4) -> 0 | Z8: =U10 -> Presentes | AA8: =W10 -> 0
B9: Fixos | R9: Bônus | U9: Saúde | W9: =SUMIF($G$11:$G$18,U9,$H$11:$H$18)+SUMIF($G$24:$G$35,U9,$H$24:$H$35)+SUMIF($N$8:$N$35,U9,$P$8:$P$35) -> 0 | X9: =IF($F$4=0,0,W9/$F$4) -> 0 | Z9: =U11 -> Beleza | AA9: =W11 -> 0
B10: Nome | D10: Pago? | E10: Data | F10: Tipo | G10: Categoria | H10: Valor | R10: Total | S10: =SUM(S8:S9) -> 0 | U10: Presentes | W10: =SUMIF($G$11:$G$18,U10,$H$11:$H$18)+SUMIF($G$24:$G$35,U10,$H$24:$H$35)+SUMIF($N$8:$N$35,U10,$P$8:$P$35) -> 0 | X10: =IF($F$4=0,0,W10/$F$4) -> 0 | Z10: =U12 -> Desenvolvimento | AA10: =W12 -> 0
U11: Beleza | W11: =SUMIF($G$11:$G$18,U11,$H$11:$H$18)+SUMIF($G$24:$G$35,U11,$H$24:$H$35)+SUMIF($N$8:$N$35,U11,$P$8:$P$35) -> 0 | X11: =IF($F$4=0,0,W11/$F$4) -> 0 | Z11: =U13 -> Lazer | AA11: =W13 -> 0
R12: Saídas | U12: Desenvolvimento | W12: =SUMIF($G$11:$G$18,U12,$H$11:$H$18)+SUMIF($G$24:$G$35,U12,$H$24:$H$35)+SUMIF($N$8:$N$35,U12,$P$8:$P$35) -> 0 | X12: =IF($F$4=0,0,W12/$F$4) -> 0 | Z12: =U14 -> Eletrônicos | AA12: =W14 -> 0
R13: Débito | S13: =SUMIF($F$11:$F$18,R13,$H$11:$H$18)+SUMIF($F$24:$F$35,R13,$H$24:$H$35)+SUMIF($M$8:$M$35,R13,$P$8:$P$35) -> 0 | U13: Lazer | W13: =SUMIF($G$11:$G$18,U13,$H$11:$H$18)+SUMIF($G$24:$G$35,U13,$H$24:$H$35)+SUMIF($N$8:$N$35,U13,$P$8:$P$35) -> 0 | X13: =IF($F$4=0,0,W13/$F$4) -> 0 | Z13: =U15 -> Assinaturas | AA13: =W15 -> 0
R14: Nubank | S14: =SUMIF($F$11:$F$18,R14,$H$11:$H$18)+SUMIF($F$24:$F$35,R14,$H$24:$H$35)+SUMIF($M$8:$M$35,R14,$P$8:$P$35) -> 0 | U14: Eletrônicos | W14: =SUMIF($G$11:$G$18,U14,$H$11:$H$18)+SUMIF($G$24:$G$35,U14,$H$24:$H$35)+SUMIF($N$8:$N$35,U14,$P$8:$P$35) -> 0 | X14: =IF($F$4=0,0,W14/$F$4) -> 0 | Z14: =U16 -> Uber transporte | AA14: =W16 -> 0
R15: Inter | S15: =SUMIF($F$11:$F$18,R15,$H$11:$H$18)+SUMIF($F$24:$F$35,R15,$H$24:$H$35)+SUMIF($M$8:$M$35,R15,$P$8:$P$35) -> 0 | U15: Assinaturas | W15: =SUMIF($G$11:$G$18,U15,$H$11:$H$18)+SUMIF($G$24:$G$35,U15,$H$24:$H$35)+SUMIF($N$8:$N$35,U15,$P$8:$P$35) -> 0 | X15: =IF($F$4=0,0,W15/$F$4) -> 0 | Z15: =U17 -> iFood/restaurante | AA15: =W17 -> 0
R16: Itaú | S16: =SUMIF($F$11:$F$18,R16,$H$11:$H$18)+SUMIF($F$24:$F$35,R16,$H$24:$H$35)+SUMIF($M$8:$M$35,R16,$P$8:$P$35) -> 0 | U16: Uber transporte | W16: =SUMIF($G$11:$G$18,U16,$H$11:$H$18)+SUMIF($G$24:$G$35,U16,$H$24:$H$35)+SUMIF($N$8:$N$35,U16,$P$8:$P$35) -> 0 | X16: =IF($F$4=0,0,W16/$F$4) -> 0 | Z16: =U18 -> Comida faculdade | AA16: =W18 -> 0
R17: Investimentos | S17: =S23 -> 0 | U17: iFood/restaurante | W17: =SUMIF($G$11:$G$18,U17,$H$11:$H$18)+SUMIF($G$24:$G$35,U17,$H$24:$H$35)+SUMIF($N$8:$N$35,U17,$P$8:$P$35) -> 0 | X17: =IF($F$4=0,0,W17/$F$4) -> 0 | Z17: =U19 -> Contas | AA17: =W19 -> 0
R18: Total | S18: =SUM(S13:S17) -> 0 | U18: Comida faculdade | W18: =SUMIF($G$11:$G$18,U18,$H$11:$H$18)+SUMIF($G$24:$G$35,U18,$H$24:$H$35)+SUMIF($N$8:$N$35,U18,$P$8:$P$35) -> 0 | X18: =IF($F$4=0,0,W18/$F$4) -> 0 | Z18: =U20 -> Outros | AA18: =W20 -> 0
U19: Contas | W19: =SUMIF($G$11:$G$18,U19,$H$11:$H$18)+SUMIF($G$24:$G$35,U19,$H$24:$H$35)+SUMIF($N$8:$N$35,U19,$P$8:$P$35) -> 0 | X19: =IF($F$4=0,0,W19/$F$4) -> 0
B20: Total de Parcelamentos | F20: =SUM(H24:H35) -> 0 | R20: Investimentos | U20: Outros | W20: =SUMIF($G$11:$G$18,U20,$H$11:$H$18)+SUMIF($G$24:$G$35,U20,$H$24:$H$35)+SUMIF($N$8:$N$35,U20,$P$8:$P$35) -> 0 | X20: =IF($F$4=0,0,W20/$F$4) -> 0
R21: Reserva
B22: Parcelamentos | R22: Renda fixa | U22: Gastos por tipo de pagamento
B23: Nome | D23: Parcelas | E23: Data | F23: Tipo | G23: Categoria | H23: Valor | R23: Total | S23: =SUM(S21:S22) -> 0 | U23: Tipo | V23: Valor | W23: Data | X23: Pago?
U24: Débito | V24: =S13 -> 0 | X24: ☐
U25: Nubank | V25: =S14 -> 0 | X25: ☐
U26: Inter | V26: =S15 -> 0 | X26: ☐
U27: Itaú | V27: =S16 -> 0 | X27: ☐
R30: Porcentagem de gastos por categoria

Sheet Fevereiro
B2: Fevereiro | Z2: Categoria | AA2: Valor gasto
R3: Saldo: | S3: =S10-S18 -> 0 | U3: Gastos do mês por categoria: | Z3: =U5 -> Mercado | AA3: =W5 -> 0
B4: Total de gastos: | F4: =F7+F20+N4 -> 0 | J4: Total de Gastos do Mês: | N4: =SUM(P8:P35) -> 0 | U4: Categoria | V4: Valor esperado | W4: Valor gasto | X4: Porcentagem | Z4: =U6 -> Despesas eventuais | AA4: =W6 -> 0
U5: Mercado | W5: =SUMIF($G$11:$G$18,U5,$H$11:$H$18)+SUMIF($G$24:$G$35,U5,$H$24:$H$35)+SUMIF($N$8:$N$35,U5,$P$8:$P$35) -> 0 | X5: =IF($F$4=0,0,W5/$F$4) -> 0 | Z5: =U7 -> Necessidades | AA5: =W7 -> 0
J6: Gastos do Mês | U6: Despesas eventuais | W6: =SUMIF($G$11:$G$18,U6,$H$11:$H$18)+SUMIF($G$24:$G$35,U6,$H$24:$H$35)+SUMIF($N$8:$N$35,U6,$P$8:$P$35) -> 0 | X6: =IF($F$4=0,0,W6/$F$4) -> 0 | Z6: =U8 -> Roupa | AA6: =W8 -> 0
B7: Total de Fixos: | F7: =SUM(H11:H18) -> 0 | J7: Nome | L7: Data | M7: Tipo | N7: Categoria | P7: Valor | R7: Entradas | U7: Necessidades | W7: =SUMIF($G$11:$G$18,U7,$H$11:$H$18)+SUMIF($G$24:$G$35,U7,$H$24:$H$35)+SUMIF($N$8:$N$35,U7,$P$8:$P$35) -> 0 | X7: =IF($F$4=0,0,W7/$F$4) -> 0 | Z7: =U9 -> Saúde | AA7: =W9 -> 0
R8: Salário | U8: Roupa | W8: =SUMIF($G$11:$G$18,U8,$H$11:$H$18)+SUMIF($G$24:$G$35,U8,$H$24:$H$35)+SUMIF($N$8:$N$35,U8,$P$8:$P$35) -> 0 | X8: =IF($F$4=0,0,W8/$F$4) -> 0 | Z8: =U10 -> Presentes | AA8: =W10 -> 0
B9: Fixos | R9: Bônus | U9: Saúde | W9: =SUMIF($G$11:$G$18,U9,$H$11:$H$18)+SUMIF($G$24:$G$35,U9,$H$24:$H$35)+SUMIF($N$8:$N$35,U9,$P$8:$P$35) -> 0 | X9: =IF($F$4=0,0,W9/$F$4) -> 0 | Z9: =U11 -> Beleza | AA9: =W11 -> 0
B10: Nome | D10: Pago? | E10: Data | F10: Tipo | G10: Categoria | H10: Valor | R10: Total | S10: =SUM(S8:S9) -> 0 | U10: Presentes | W10: =SUMIF($G$11:$G$18,U10,$H$11:$H$18)+SUMIF($G$24:$G$35,U10,$H$24:$H$35)+SUMIF($N$8:$N$35,U10,$P$8:$P$35) -> 0 | X10: =IF($F$4=0,0,W10/$F$4) -> 0 | Z10: =U12 -> Desenvolvimento | AA10: =W12 -> 0
U11: Beleza | W11: =SUMIF($G$11:$G$18,U11,$H$11:$H$18)+SUMIF($G$24:$G$35,U11,$H$24:$H$35)+SUMIF($N$8:$N$35,U11,$P$8:$P$35) -> 0 | X11: =IF($F$4=0,0,W11/$F$4) -> 0 | Z11: =U13 -> Lazer | AA11: =W13 -> 0
R12: Saídas | U12: Desenvolvimento | W12: =SUMIF($G$11:$G$18,U12,$H$11:$H$18)+SUMIF($G$24:$G$35,U12,$H$24:$H$35)+SUMIF($N$8:$N$35,U12,$P$8:$P$35) -> 0 | X12: =IF($F$4=0,0,W12/$F$4) -> 0 | Z12: =U14 -> Eletrônicos | AA12: =W14 -> 0
R13: Débito | S13: =SUMIF($F$11:$F$18,R13,$H$11:$H$18)+SUMIF($F$24:$F$35,R13,$H$24:$H$35)+SUMIF($M$8:$M$35,R13,$P$8:$P$35) -> 0 | U13: Lazer | W13: =SUMIF($G$11:$G$18,U13,$H$11:$H$18)+SUMIF($G$24:$G$35,U13,$H$24:$H$35)+SUMIF($N$8:$N$35,U13,$P$8:$P$35) -> 0 | X13: =IF($F$4=0,0,W13/$F$4) -> 0 | Z13: =U15 -> Assinaturas | AA13: =W15 -> 0
R14: Nubank | S14: =SUMIF($F$11:$F$18,R14,$H$11:$H$18)+SUMIF($F$24:$F$35,R14,$H$24:$H$35)+SUMIF($M$8:$M$35,R14,$P$8:$P$35) -> 0 | U14: Eletrônicos | W14: =SUMIF($G$11:$G$18,U14,$H$11:$H$18)+SUMIF($G$24:$G$35,U14,$H$24:$H$35)+SUMIF($N$8:$N$35,U14,$P$8:$P$35) -> 0 | X14: =IF($F$4=0,0,W14/$F$4) -> 0 | Z14: =U16 -> Uber transporte | AA14: =W16 -> 0
R15: Inter | S15: =SUMIF($F$11:$F$18,R15,$H$11:$H$18)+SUMIF($F$24:$F$35,R15,$H$24:$H$35)+SUMIF($M$8:$M$35,R15,$P$8:$P$35) -> 0 | U15: Assinaturas | W15: =SUMIF($G$11:$G$18,U15,$H$11:$H$18)+SUMIF($G$24:$G$35,U15,$H$24:$H$35)+SUMIF($N$8:$N$35,U15,$P$8:$P$35) -> 0 | X15: =IF($F$4=0,0,W15/$F$4) -> 0 | Z15: =U17 -> iFood/restaurante | AA15: =W17 -> 0
R16: Itaú | S16: =SUMIF($F$11:$F$18,R16,$H$11:$H$18)+SUMIF($F$24:$F$35,R16,$H$24:$H$35)+SUMIF($M$8:$M$35,R16,$P$8:$P$35) -> 0 | U16: Uber transporte | W16: =SUMIF($G$11:$G$18,U16,$H$11:$H$18)+SUMIF($G$24:$G$35,U16,$H$24:$H$35)+SUMIF($N$8:$N$35,U16,$P$8:$P$35) -> 0 | X16: =IF($F$4=0,0,W16/$F$4) -> 0 | Z16: =U18 -> Comida faculdade | AA16: =W18 -> 0
R17: Investimentos | S17: =S23 -> 0 | U17: iFood/restaurante | W17: =SUMIF($G$11:$G$18,U17,$H$11:$H$18)+SUMIF($G$24:$G$35,U17,$H$24:$H$35)+SUMIF($N$8:$N$35,U17,$P$8:$P$35) -> 0 | X17: =IF($F$4=0,0,W17/$F$4) -> 0 | Z17: =U19 -> Contas | AA17: =W19 -> 0
R18: Total | S18: =SUM(S13:S17) -> 0 | U18: Comida faculdade | W18: =SUMIF($G$11:$G$18,U18,$H$11:$H$18)+SUMIF($G$24:$G$35,U18,$H$24:$H$35)+SUMIF($N$8:$N$35,U18,$P$8:$P$35) -> 0 | X18: =IF($F$4=0,0,W18/$F$4) -> 0 | Z18: =U20 -> Outros | AA18: =W20 -> 0
U19: Contas | W19: =SUMIF($G$11:$G$18,U19,$H$11:$H$18)+SUMIF($G$24:$G$35,U19,$H$24:$H$35)+SUMIF($N$8:$N$35,U19,$P$8:$P$35) -> 0 | X19: =IF($F$4=0,0,W19/$F$4) -> 0
B20: Total de Parcelamentos | F20: =SUM(H24:H35) -> 0 | R20: Investimentos | U20: Outros | W20: =SUMIF($G$11:$G$18,U20,$H$11:$H$18)+SUMIF($G$24:$G$35,U20,$H$24:$H$35)+SUMIF($N$8:$N$35,U20,$P$8:$P$35) -> 0 | X20: =IF($F$4=0,0,W20/$F$4) -> 0
R21: Reserva
B22: Parcelamentos | R22: Renda fixa | U22: Gastos por tipo de pagamento
B23: Nome | D23: Parcelas | E23: Data | F23: Tipo | G23: Categoria | H23: Valor | R23: Total | S23: =SUM(S21:S22) -> 0 | U23: Tipo | V23: Valor | W23: Data | X23: Pago?
U24: Débito | V24: =S13 -> 0 | X24: ☐
U25: Nubank | V25: =S14 -> 0 | X25: ☐
U26: Inter | V26: =S15 -> 0 | X26: ☐
U27: Itaú | V27: =S16 -> 0 | X27: ☐
R30: Porcentagem de gastos por categoria

Sheet Março
B2: Março | Z2: Categoria | AA2: Valor gasto
R3: Saldo: | S3: =S10-S18 -> 0 | U3: Gastos do mês por categoria: | Z3: =U5 -> Mercado | AA3: =W5 -> 0
B4: Total de gastos: | F4: =F7+F20+N4 -> 0 | J4: Total de Gastos do Mês: | N4: =SUM(P8:P35) -> 0 | U4: Categoria | V4: Valor esperado | W4: Valor gasto | X4: Porcentagem | Z4: =U6 -> Despesas eventuais | AA4: =W6 -> 0
U5: Mercado | W5: =SUMIF($G$11:$G$18,U5,$H$11:$H$18)+SUMIF($G$24:$G$35,U5,$H$24:$H$35)+SUMIF($N$8:$N$35,U5,$P$8:$P$35) -> 0 | X5: =IF($F$4=0,0,W5/$F$4) -> 0 | Z5: =U7 -> Necessidades | AA5: =W7 -> 0
J6: Gastos do Mês | U6: Despesas eventuais | W6: =SUMIF($G$11:$G$18,U6,$H$11:$H$18)+SUMIF($G$24:$G$35,U6,$H$24:$H$35)+SUMIF($N$8:$N$35,U6,$P$8:$P$35) -> 0 | X6: =IF($F$4=0,0,W6/$F$4) -> 0 | Z6: =U8 -> Roupa | AA6: =W8 -> 0
B7: Total de Fixos: | F7: =SUM(H11:H18) -> 0 | J7: Nome | L7: Data | M7: Tipo | N7: Categoria | P7: Valor | R7: Entradas | U7: Necessidades | W7: =SUMIF($G$11:$G$18,U7,$H$11:$H$18)+SUMIF($G$24:$G$35,U7,$H$24:$H$35)+SUMIF($N$8:$N$35,U7,$P$8:$P$35) -> 0 | X7: =IF($F$4=0,0,W7/$F$4) -> 0 | Z7: =U9 -> Saúde | AA7: =W9 -> 0
R8: Salário | U8: Roupa | W8: =SUMIF($G$11:$G$18,U8,$H$11:$H$18)+SUMIF($G$24:$G$35,U8,$H$24:$H$35)+SUMIF($N$8:$N$35,U8,$P$8:$P$35) -> 0 | X8: =IF($F$4=0,0,W8/$F$4) -> 0 | Z8: =U10 -> Presentes | AA8: =W10 -> 0
B9: Fixos | R9: Bônus | U9: Saúde | W9: =SUMIF($G$11:$G$18,U9,$H$11:$H$18)+SUMIF($G$24:$G$35,U9,$H$24:$H$35)+SUMIF($N$8:$N$35,U9,$P$8:$P$35) -> 0 | X9: =IF($F$4=0,0,W9/$F$4) -> 0 | Z9: =U11 -> Beleza | AA9: =W11 -> 0
B10: Nome | D10: Pago? | E10: Data | F10: Tipo | G10: Categoria | H10: Valor | R10: Total | S10: =SUM(S8:S9) -> 0 | U10: Presentes | W10: =SUMIF($G$11:$G$18,U10,$H$11:$H$18)+SUMIF($G$24:$G$35,U10,$H$24:$H$35)+SUMIF($N$8:$N$35,U10,$P$8:$P$35) -> 0 | X10: =IF($F$4=0,0,W10/$F$4) -> 0 | Z10: =U12 -> Desenvolvimento | AA10: =W12 -> 0
U11: Beleza | W11: =SUMIF($G$11:$G$18,U11,$H$11:$H$18)+SUMIF($G$24:$G$35,U11,$H$24:$H$35)+SUMIF($N$8:$N$35,U11,$P$8:$P$35) -> 0 | X11: =IF($F$4=0,0,W11/$F$4) -> 0 | Z11: =U13 -> Lazer | AA11: =W13 -> 0
R12: Saídas | U12: Desenvolvimento | W12: =SUMIF($G$11:$G$18,U12,$H$11:$H$18)+SUMIF($G$24:$G$35,U12,$H$24:$H$35)+SUMIF($N$8:$N$35,U12,$P$8:$P$35) -> 0 | X12: =IF($F$4=0,0,W12/$F$4) -> 0 | Z12: =U14 -> Eletrônicos | AA12: =W14 -> 0
R13: Débito | S13: =SUMIF($F$11:$F$18,R13,$H$11:$H$18)+SUMIF($F$24:$F$35,R13,$H$24:$H$35)+SUMIF($M$8:$M$35,R13,$P$8:$P$35) -> 0 | U13: Lazer | W13: =SUMIF($G$11:$G$18,U13,$H$11:$H$18)+SUMIF($G$24:$G$35,U13,$H$24:$H$35)+SUMIF($N$8:$N$35,U13,$P$8:$P$35) -> 0 | X13: =IF($F$4=0,0,W13/$F$4) -> 0 | Z13: =U15 -> Assinaturas | AA13: =W15 -> 0
R14: Nubank | S14: =SUMIF($F$11:$F$18,R14,$H$11:$H$18)+SUMIF($F$24:$F$35,R14,$H$24:$H$35)+SUMIF($M$8:$M$35,R14,$P$8:$P$35) -> 0 | U14: Eletrônicos | W14: =SUMIF($G$11:$G$18,U14,$H$11:$H$18)+SUMIF($G$24:$G$35,U14,$H$24:$H$35)+SUMIF($N$8:$N$35,U14,$P$8:$P$35) -> 0 | X14: =IF($F$4=0,0,W14/$F$4) -> 0 | Z14: =U16 -> Uber transporte | AA14: =W16 -> 0
R15: Inter | S15: =SUMIF($F$11:$F$18,R15,$H$11:$H$18)+SUMIF($F$24:$F$35,R15,$H$24:$H$35)+SUMIF($M$8:$M$35,R15,$P$8:$P$35) -> 0 | U15: Assinaturas | W15: =SUMIF($G$11:$G$18,U15,$H$11:$H$18)+SUMIF($G$24:$G$35,U15,$H$24:$H$35)+SUMIF($N$8:$N$35,U15,$P$8:$P$35) -> 0 | X15: =IF($F$4=0,0,W15/$F$4) -> 0 | Z15: =U17 -> iFood/restaurante | AA15: =W17 -> 0
R16: Itaú | S16: =SUMIF($F$11:$F$18,R16,$H$11:$H$18)+SUMIF($F$24:$F$35,R16,$H$24:$H$35)+SUMIF($M$8:$M$35,R16,$P$8:$P$35) -> 0 | U16: Uber transporte | W16: =SUMIF($G$11:$G$18,U16,$H$11:$H$18)+SUMIF($G$24:$G$35,U16,$H$24:$H$35)+SUMIF($N$8:$N$35,U16,$P$8:$P$35) -> 0 | X16: =IF($F$4=0,0,W16/$F$4) -> 0 | Z16: =U18 -> Comida faculdade | AA16: =W18 -> 0
R17: Investimentos | S17: =S23 -> 0 | U17: iFood/restaurante | W17: =SUMIF($G$11:$G$18,U17,$H$11:$H$18)+SUMIF($G$24:$G$35,U17,$H$24:$H$35)+SUMIF($N$8:$N$35,U17,$P$8:$P$35) -> 0 | X17: =IF($F$4=0,0,W17/$F$4) -> 0 | Z17: =U19 -> Contas | AA17: =W19 -> 0
R18: Total | S18: =SUM(S13:S17) -> 0 | U18: Comida faculdade | W18: =SUMIF($G$11:$G$18,U18,$H$11:$H$18)+SUMIF($G$24:$G$35,U18,$H$24:$H$35)+SUMIF($N$8:$N$35,U18,$P$8:$P$35) -> 0 | X18: =IF($F$4=0,0,W18/$F$4) -> 0 | Z18: =U20 -> Outros | AA18: =W20 -> 0
U19: Contas | W19: =SUMIF($G$11:$G$18,U19,$H$11:$H$18)+SUMIF($G$24:$G$35,U19,$H$24:$H$35)+SUMIF($N$8:$N$35,U19,$P$8:$P$35) -> 0 | X19: =IF($F$4=0,0,W19/$F$4) -> 0
B20: Total de Parcelamentos | F20: =SUM(H24:H35) -> 0 | R20: Investimentos | U20: Outros | W20: =SUMIF($G$11:$G$18,U20,$H$11:$H$18)+SUMIF($G$24:$G$35,U20,$H$24:$H$35)+SUMIF($N$8:$N$35,U20,$P$8:$P$35) -> 0 | X20: =IF($F$4=0,0,W20/$F$4) -> 0
R21: Reserva
B22: Parcelamentos | R22: Renda fixa | U22: Gastos por tipo de pagamento
B23: Nome | D23: Parcelas | E23: Data | F23: Tipo | G23: Categoria | H23: Valor | R23: Total | S23: =SUM(S21:S22) -> 0 | U23: Tipo | V23: Valor | W23: Data | X23: Pago?
U24: Débito | V24: =S13 -> 0 | X24: ☐
U25: Nubank | V25: =S14 -> 0 | X25: ☐
U26: Inter | V26: =S15 -> 0 | X26: ☐
U27: Itaú | V27: =S16 -> 0 | X27: ☐
R30: Porcentagem de gastos por categoria

Sheet Abril
B2: Abril | Z2: Categoria | AA2: Valor gasto
R3: Saldo: | S3: =S10-S18 -> 0 | U3: Gastos do mês por categoria: | Z3: =U5 -> Mercado | AA3: =W5 -> 0
B4: Total de gastos: | F4: =F7+F20+N4 -> 0 | J4: Total de Gastos do Mês: | N4: =SUM(P8:P35) -> 0 | U4: Categoria | V4: Valor esperado | W4: Valor gasto | X4: Porcentagem | Z4: =U6 -> Despesas eventuais | AA4: =W6 -> 0
U5: Mercado | W5: =SUMIF($G$11:$G$18,U5,$H$11:$H$18)+SUMIF($G$24:$G$35,U5,$H$24:$H$35)+SUMIF($N$8:$N$35,U5,$P$8:$P$35) -> 0 | X5: =IF($F$4=0,0,W5/$F$4) -> 0 | Z5: =U7 -> Necessidades | AA5: =W7 -> 0
J6: Gastos do Mês | U6: Despesas eventuais | W6: =SUMIF($G$11:$G$18,U6,$H$11:$H$18)+SUMIF($G$24:$G$35,U6,$H$24:$H$35)+SUMIF($N$8:$N$35,U6,$P$8:$P$35) -> 0 | X6: =IF($F$4=0,0,W6/$F$4) -> 0 | Z6: =U8 -> Roupa | AA6: =W8 -> 0
B7: Total de Fixos: | F7: =SUM(H11:H18) -> 0 | J7: Nome | L7: Data | M7: Tipo | N7: Categoria | P7: Valor | R7: Entradas | U7: Necessidades | W7: =SUMIF($G$11:$G$18,U7,$H$11:$H$18)+SUMIF($G$24:$G$35,U7,$H$24:$H$35)+SUMIF($N$8:$N$35,U7,$P$8:$P$35) -> 0 | X7: =IF($F$4=0,0,W7/$F$4) -> 0 | Z7: =U9 -> Saúde | AA7: =W9 -> 0
R8: Salário | U8: Roupa | W8: =SUMIF($G$11:$G$18,U8,$H$11:$H$18)+SUMIF($G$24:$G$35,U8,$H$24:$H$35)+SUMIF($N$8:$N$35,U8,$P$8:$P$35) -> 0 | X8: =IF($F$4=0,0,W8/$F$4) -> 0 | Z8: =U10 -> Presentes | AA8: =W10 -> 0
B9: Fixos | R9: Bônus | U9: Saúde | W9: =SUMIF($G$11:$G$18,U9,$H$11:$H$18)+SUMIF($G$24:$G$35,U9,$H$24:$H$35)+SUMIF($N$8:$N$35,U9,$P$8:$P$35) -> 0 | X9: =IF($F$4=0,0,W9/$F$4) -> 0 | Z9: =U11 -> Beleza | AA9: =W11 -> 0
B10: Nome | D10: Pago? | E10: Data | F10: Tipo | G10: Categoria | H10: Valor | R10: Total | S10: =SUM(S8:S9) -> 0 | U10: Presentes | W10: =SUMIF($G$11:$G$18,U10,$H$11:$H$18)+SUMIF($G$24:$G$35,U10,$H$24:$H$35)+SUMIF($N$8:$N$35,U10,$P$8:$P$35) -> 0 | X10: =IF($F$4=0,0,W10/$F$4) -> 0 | Z10: =U12 -> Desenvolvimento | AA10: =W12 -> 0
U11: Beleza | W11: =SUMIF($G$11:$G$18,U11,$H$11:$H$18)+SUMIF($G$24:$G$35,U11,$H$24:$H$35)+SUMIF($N$8:$N$35,U11,$P$8:$P$35) -> 0 | X11: =IF($F$4=0,0,W11/$F$4) -> 0 | Z11: =U13 -> Lazer | AA11: =W13 -> 0
R12: Saídas | U12: Desenvolvimento | W12: =SUMIF($G$11:$G$18,U12,$H$11:$H$18)+SUMIF($G$24:$G$35,U12,$H$24:$H$35)+SUMIF($N$8:$N$35,U12,$P$8:$P$35) -> 0 | X12: =IF($F$4=0,0,W12/$F$4) -> 0 | Z12: =U14 -> Eletrônicos | AA12: =W14 -> 0
R13: Débito | S13: =SUMIF($F$11:$F$18,R13,$H$11:$H$18)+SUMIF($F$24:$F$35,R13,$H$24:$H$35)+SUMIF($M$8:$M$35,R13,$P$8:$P$35) -> 0 | U13: Lazer | W13: =SUMIF($G$11:$G$18,U13,$H$11:$H$18)+SUMIF($G$24:$G$35,U13,$H$24:$H$35)+SUMIF($N$8:$N$35,U13,$P$8:$P$35) -> 0 | X13: =IF($F$4=0,0,W13/$F$4) -> 0 | Z13: =U15 -> Assinaturas | AA13: =W15 -> 0
R14: Nubank | S14: =SUMIF($F$11:$F$18,R14,$H$11:$H$18)+SUMIF($F$24:$F$35,R14,$H$24:$H$35)+SUMIF($M$8:$M$35,R14,$P$8:$P$35) -> 0 | U14: Eletrônicos | W14: =SUMIF($G$11:$G$18,U14,$H$11:$H$18)+SUMIF($G$24:$G$35,U14,$H$24:$H$35)+SUMIF($N$8:$N$35,U14,$P$8:$P$35) -> 0 | X14: =IF($F$4=0,0,W14/$F$4) -> 0 | Z14: =U16 -> Uber transporte | AA14: =W16 -> 0
R15: Inter | S15: =SUMIF($F$11:$F$18,R15,$H$11:$H$18)+SUMIF($F$24:$F$35,R15,$H$24:$H$35)+SUMIF($M$8:$M$35,R15,$P$8:$P$35) -> 0 | U15: Assinaturas | W15: =SUMIF($G$11:$G$18,U15,$H$11:$H$18)+SUMIF($G$24:$G$35,U15,$H$24:$H$35)+SUMIF($N$8:$N$35,U15,$P$8:$P$35) -> 0 | X15: =IF($F$4=0,0,W15/$F$4) -> 0 | Z15: =U17 -> iFood/restaurante | AA15: =W17 -> 0
R16: Itaú | S16: =SUMIF($F$11:$F$18,R16,$H$11:$H$18)+SUMIF($F$24:$F$35,R16,$H$24:$H$35)+SUMIF($M$8:$M$35,R16,$P$8:$P$35) -> 0 | U16: Uber transporte | W16: =SUMIF($G$11:$G$18,U16,$H$11:$H$18)+SUMIF($G$24:$G$35,U16,$H$24:$H$35)+SUMIF($N$8:$N$35,U16,$P$8:$P$35) -> 0 | X16: =IF($F$4=0,0,W16/$F$4) -> 0 | Z16: =U18 -> Comida faculdade | AA16: =W18 -> 0
R17: Investimentos | S17: =S23 -> 0 | U17: iFood/restaurante | W17: =SUMIF($G$11:$G$18,U17,$H$11:$H$18)+SUMIF($G$24:$G$35,U17,$H$24:$H$35)+SUMIF($N$8:$N$35,U17,$P$8:$P$35) -> 0 | X17: =IF($F$4=0,0,W17/$F$4) -> 0 | Z17: =U19 -> Contas | AA17: =W19 -> 0
R18: Total | S18: =SUM(S13:S17) -> 0 | U18: Comida faculdade | W18: =SUMIF($G$11:$G$18,U18,$H$11:$H$18)+SUMIF($G$24:$G$35,U18,$H$24:$H$35)+SUMIF($N$8:$N$35,U18,$P$8:$P$35) -> 0 | X18: =IF($F$4=0,0,W18/$F$4) -> 0 | Z18: =U20 -> Outros | AA18: =W20 -> 0
U19: Contas | W19: =SUMIF($G$11:$G$18,U19,$H$11:$H$18)+SUMIF($G$24:$G$35,U19,$H$24:$H$35)+SUMIF($N$8:$N$35,U19,$P$8:$P$35) -> 0 | X19: =IF($F$4=0,0,W19/$F$4) -> 0
B20: Total de Parcelamentos | F20: =SUM(H24:H35) -> 0 | R20: Investimentos | U20: Outros | W20: =SUMIF($G$11:$G$18,U20,$H$11:$H$18)+SUMIF($G$24:$G$35,U20,$H$24:$H$35)+SUMIF($N$8:$N$35,U20,$P$8:$P$35) -> 0 | X20: =IF($F$4=0,0,W20/$F$4) -> 0
R21: Reserva
B22: Parcelamentos | R22: Renda fixa | U22: Gastos por tipo de pagamento
B23: Nome | D23: Parcelas | E23: Data | F23: Tipo | G23: Categoria | H23: Valor | R23: Total | S23: =SUM(S21:S22) -> 0 | U23: Tipo | V23: Valor | W23: Data | X23: Pago?
U24: Débito | V24: =S13 -> 0 | X24: ☐
U25: Nubank | V25: =S14 -> 0 | X25: ☐
U26: Inter | V26: =S15 -> 0 | X26: ☐
U27: Itaú | V27: =S16 -> 0 | X27: ☐
R30: Porcentagem de gastos por categoria

Sheet Maio
B2: Maio | Z2: Categoria | AA2: Valor gasto
R3: Saldo: | S3: =S10-S18 -> 0 | U3: Gastos do mês por categoria: | Z3: =U5 -> Mercado | AA3: =W5 -> 0
B4: Total de gastos: | F4: =F7+F20+N4 -> 0 | J4: Total de Gastos do Mês: | N4: =SUM(P8:P35) -> 0 | U4: Categoria | V4: Valor esperado | W4: Valor gasto | X4: Porcentagem | Z4: =U6 -> Despesas eventuais | AA4: =W6 -> 0
U5: Mercado | W5: =SUMIF($G$11:$G$18,U5,$H$11:$H$18)+SUMIF($G$24:$G$35,U5,$H$24:$H$35)+SUMIF($N$8:$N$35,U5,$P$8:$P$35) -> 0 | X5: =IF($F$4=0,0,W5/$F$4) -> 0 | Z5: =U7 -> Necessidades | AA5: =W7 -> 0
J6: Gastos do Mês | U6: Despesas eventuais | W6: =SUMIF($G$11:$G$18,U6,$H$11:$H$18)+SUMIF($G$24:$G$35,U6,$H$24:$H$35)+SUMIF($N$8:$N$35,U6,$P$8:$P$35) -> 0 | X6: =IF($F$4=0,0,W6/$F$4) -> 0 | Z6: =U8 -> Roupa | AA6: =W8 -> 0
B7: Total de Fixos: | F7: =SUM(H11:H18) -> 0 | J7: Nome | L7: Data | M7: Tipo | N7: Categoria | P7: Valor | R7: Entradas | U7: Necessidades | W7: =SUMIF($G$11:$G$18,U7,$H$11:$H$18)+SUMIF($G$24:$G$35,U7,$H$24:$H$35)+SUMIF($N$8:$N$35,U7,$P$8:$P$35) -> 0 | X7: =IF($F$4=0,0,W7/$F$4) -> 0 | Z7: =U9 -> Saúde | AA7: =W9 -> 0
R8: Salário | U8: Roupa | W8: =SUMIF($G$11:$G$18,U8,$H$11:$H$18)+SUMIF($G$24:$G$35,U8,$H$24:$H$35)+SUMIF($N$8:$N$35,U8,$P$8:$P$35) -> 0 | X8: =IF($F$4=0,0,W8/$F$4) -> 0 | Z8: =U10 -> Presentes | AA8: =W10 -> 0
B9: Fixos | R9: Bônus | U9: Saúde | W9: =SUMIF($G$11:$G$18,U9,$H$11:$H$18)+SUMIF($G$24:$G$35,U9,$H$24:$H$35)+SUMIF($N$8:$N$35,U9,$P$8:$P$35) -> 0 | X9: =IF($F$4=0,0,W9/$F$4) -> 0 | Z9: =U11 -> Beleza | AA9: =W11 -> 0
B10: Nome | D10: Pago? | E10: Data | F10: Tipo | G10: Categoria | H10: Valor | R10: Total | S10: =SUM(S8:S9) -> 0 | U10: Presentes | W10: =SUMIF($G$11:$G$18,U10,$H$11:$H$18)+SUMIF($G$24:$G$35,U10,$H$24:$H$35)+SUMIF($N$8:$N$35,U10,$P$8:$P$35) -> 0 | X10: =IF($F$4=0,0,W10/$F$4) -> 0 | Z10: =U12 -> Desenvolvimento | AA10: =W12 -> 0
U11: Beleza | W11: =SUMIF($G$11:$G$18,U11,$H$11:$H$18)+SUMIF($G$24:$G$35,U11,$H$24:$H$35)+SUMIF($N$8:$N$35,U11,$P$8:$P$35) -> 0 | X11: =IF($F$4=0,0,W11/$F$4) -> 0 | Z11: =U13 -> Lazer | AA11: =W13 -> 0
R12: Saídas | U12: Desenvolvimento | W12: =SUMIF($G$11:$G$18,U12,$H$11:$H$18)+SUMIF($G$24:$G$35,U12,$H$24:$H$35)+SUMIF($N$8:$N$35,U12,$P$8:$P$35) -> 0 | X12: =IF($F$4=0,0,W12/$F$4) -> 0 | Z12: =U14 -> Eletrônicos | AA12: =W14 -> 0
R13: Débito | S13: =SUMIF($F$11:$F$18,R13,$H$11:$H$18)+SUMIF($F$24:$F$35,R13,$H$24:$H$35)+SUMIF($M$8:$M$35,R13,$P$8:$P$35) -> 0 | U13: Lazer | W13: =SUMIF($G$11:$G$18,U13,$H$11:$H$18)+SUMIF($G$24:$G$35,U13,$H$24:$H$35)+SUMIF($N$8:$N$35,U13,$P$8:$P$35) -> 0 | X13: =IF($F$4=0,0,W13/$F$4) -> 0 | Z13: =U15 -> Assinaturas | AA13: =W15 -> 0
R14: Nubank | S14: =SUMIF($F$11:$F$18,R14,$H$11:$H$18)+SUMIF($F$24:$F$35,R14,$H$24:$H$35)+SUMIF($M$8:$M$35,R14,$P$8:$P$35) -> 0 | U14: Eletrônicos | W14: =SUMIF($G$11:$G$18,U14,$H$11:$H$18)+SUMIF($G$24:$G$35,U14,$H$24:$H$35)+SUMIF($N$8:$N$35,U14,$P$8:$P$35) -> 0 | X14: =IF($F$4=0,0,W14/$F$4) -> 0 | Z14: =U16 -> Uber transporte | AA14: =W16 -> 0
R15: Inter | S15: =SUMIF($F$11:$F$18,R15,$H$11:$H$18)+SUMIF($F$24:$F$35,R15,$H$24:$H$35)+SUMIF($M$8:$M$35,R15,$P$8:$P$35) -> 0 | U15: Assinaturas | W15: =SUMIF($G$11:$G$18,U15,$H$11:$H$18)+SUMIF($G$24:$G$35,U15,$H$24:$H$35)+SUMIF($N$8:$N$35,U15,$P$8:$P$35) -> 0 | X15: =IF($F$4=0,0,W15/$F$4) -> 0 | Z15: =U17 -> iFood/restaurante | AA15: =W17 -> 0
R16: Itaú | S16: =SUMIF($F$11:$F$18,R16,$H$11:$H$18)+SUMIF($F$24:$F$35,R16,$H$24:$H$35)+SUMIF($M$8:$M$35,R16,$P$8:$P$35) -> 0 | U16: Uber transporte | W16: =SUMIF($G$11:$G$18,U16,$H$11:$H$18)+SUMIF($G$24:$G$35,U16,$H$24:$H$35)+SUMIF($N$8:$N$35,U16,$P$8:$P$35) -> 0 | X16: =IF($F$4=0,0,W16/$F$4) -> 0 | Z16: =U18 -> Comida faculdade | AA16: =W18 -> 0
R17: Investimentos | S17: =S23 -> 0 | U17: iFood/restaurante | W17: =SUMIF($G$11:$G$18,U17,$H$11:$H$18)+SUMIF($G$24:$G$35,U17,$H$24:$H$35)+SUMIF($N$8:$N$35,U17,$P$8:$P$35) -> 0 | X17: =IF($F$4=0,0,W17/$F$4) -> 0 | Z17: =U19 -> Contas | AA17: =W19 -> 0
R18: Total | S18: =SUM(S13:S17) -> 0 | U18: Comida faculdade | W18: =SUMIF($G$11:$G$18,U18,$H$11:$H$18)+SUMIF($G$24:$G$35,U18,$H$24:$H$35)+SUMIF($N$8:$N$35,U18,$P$8:$P$35) -> 0 | X18: =IF($F$4=0,0,W18/$F$4) -> 0 | Z18: =U20 -> Outros | AA18: =W20 -> 0
U19: Contas | W19: =SUMIF($G$11:$G$18,U19,$H$11:$H$18)+SUMIF($G$24:$G$35,U19,$H$24:$H$35)+SUMIF($N$8:$N$35,U19,$P$8:$P$35) -> 0 | X19: =IF($F$4=0,0,W19/$F$4) -> 0
B20: Total de Parcelamentos | F20: =SUM(H24:H35) -> 0 | R20: Investimentos | U20: Outros | W20: =SUMIF($G$11:$G$18,U20,$H$11:$H$18)+SUMIF($G$24:$G$35,U20,$H$24:$H$35)+SUMIF($N$8:$N$35,U20,$P$8:$P$35) -> 0 | X20: =IF($F$4=0,0,W20/$F$4) -> 0
R21: Reserva
B22: Parcelamentos | R22: Renda fixa | U22: Gastos por tipo de pagamento
B23: Nome | D23: Parcelas | E23: Data | F23: Tipo | G23: Categoria | H23: Valor | R23: Total | S23: =SUM(S21:S22) -> 0 | U23: Tipo | V23: Valor | W23: Data | X23: Pago?
U24: Débito | V24: =S13 -> 0 | X24: ☐
U25: Nubank | V25: =S14 -> 0 | X25: ☐
U26: Inter | V26: =S15 -> 0 | X26: ☐
U27: Itaú | V27: =S16 -> 0 | X27: ☐
R30: Porcentagem de gastos por categoria

Sheet Junho
B2: Junho | Z2: Categoria | AA2: Valor gasto
R3: Saldo: | S3: =S10-S18 -> 0 | U3: Gastos do mês por categoria: | Z3: =U5 -> Mercado | AA3: =W5 -> 0
B4: Total de gastos: | F4: =F7+F20+N4 -> 0 | J4: Total de Gastos do Mês: | N4: =SUM(P8:P35) -> 0 | U4: Categoria | V4: Valor esperado | W4: Valor gasto | X4: Porcentagem | Z4: =U6 -> Despesas eventuais | AA4: =W6 -> 0
U5: Mercado | W5: =SUMIF($G$11:$G$18,U5,$H$11:$H$18)+SUMIF($G$24:$G$35,U5,$H$24:$H$35)+SUMIF($N$8:$N$35,U5,$P$8:$P$35) -> 0 | X5: =IF($F$4=0,0,W5/$F$4) -> 0 | Z5: =U7 -> Necessidades | AA5: =W7 -> 0
J6: Gastos do Mês | U6: Despesas eventuais | W6: =SUMIF($G$11:$G$18,U6,$H$11:$H$18)+SUMIF($G$24:$G$35,U6,$H$24:$H$35)+SUMIF($N$8:$N$35,U6,$P$8:$P$35) -> 0 | X6: =IF($F$4=0,0,W6/$F$4) -> 0 | Z6: =U8 -> Roupa | AA6: =W8 -> 0
B7: Total de Fixos: | F7: =SUM(H11:H18) -> 0 | J7: Nome | L7: Data | M7: Tipo | N7: Categoria | P7: Valor | R7: Entradas | U7: Necessidades | W7: =SUMIF($G$11:$G$18,U7,$H$11:$H$18)+SUMIF($G$24:$G$35,U7,$H$24:$H$35)+SUMIF($N$8:$N$35,U7,$P$8:$P$35) -> 0 | X7: =IF($F$4=0,0,W7/$F$4) -> 0 | Z7: =U9 -> Saúde | AA7: =W9 -> 0
R8: Salário | U8: Roupa | W8: =SUMIF($G$11:$G$18,U8,$H$11:$H$18)+SUMIF($G$24:$G$35,U8,$H$24:$H$35)+SUMIF($N$8:$N$35,U8,$P$8:$P$35) -> 0 | X8: =IF($F$4=0,0,W8/$F$4) -> 0 | Z8: =U10 -> Presentes | AA8: =W10 -> 0
B9: Fixos | R9: Bônus | U9: Saúde | W9: =SUMIF($G$11:$G$18,U9,$H$11:$H$18)+SUMIF($G$24:$G$35,U9,$H$24:$H$35)+SUMIF($N$8:$N$35,U9,$P$8:$P$35) -> 0 | X9: =IF($F$4=0,0,W9/$F$4) -> 0 | Z9: =U11 -> Beleza | AA9: =W11 -> 0
B10: Nome | D10: Pago? | E10: Data | F10: Tipo | G10: Categoria | H10: Valor | R10: Total | S10: =SUM(S8:S9) -> 0 | U10: Presentes | W10: =SUMIF($G$11:$G$18,U10,$H$11:$H$18)+SUMIF($G$24:$G$35,U10,$H$24:$H$35)+SUMIF($N$8:$N$35,U10,$P$8:$P$35) -> 0 | X10: =IF($F$4=0,0,W10/$F$4) -> 0 | Z10: =U12 -> Desenvolvimento | AA10: =W12 -> 0
U11: Beleza | W11: =SUMIF($G$11:$G$18,U11,$H$11:$H$18)+SUMIF($G$24:$G$35,U11,$H$24:$H$35)+SUMIF($N$8:$N$35,U11,$P$8:$P$35) -> 0 | X11: =IF($F$4=0,0,W11/$F$4) -> 0 | Z11: =U13 -> Lazer | AA11: =W13 -> 0
R12: Saídas | U12: Desenvolvimento | W12: =SUMIF($G$11:$G$18,U12,$H$11:$H$18)+SUMIF($G$24:$G$35,U12,$H$24:$H$35)+SUMIF($N$8:$N$35,U12,$P$8:$P$35) -> 0 | X12: =IF($F$4=0,0,W12/$F$4) -> 0 | Z12: =U14 -> Eletrônicos | AA12: =W14 -> 0
R13: Débito | S13: =SUMIF($F$11:$F$18,R13,$H$11:$H$18)+SUMIF($F$24:$F$35,R13,$H$24:$H$35)+SUMIF($M$8:$M$35,R13,$P$8:$P$35) -> 0 | U13: Lazer | W13: =SUMIF($G$11:$G$18,U13,$H$11:$H$18)+SUMIF($G$24:$G$35,U13,$H$24:$H$35)+SUMIF($N$8:$N$35,U13,$P$8:$P$35) -> 0 | X13: =IF($F$4=0,0,W13/$F$4) -> 0 | Z13: =U15 -> Assinaturas | AA13: =W15 -> 0
R14: Nubank | S14: =SUMIF($F$11:$F$18,R14,$H$11:$H$18)+SUMIF($F$24:$F$35,R14,$H$24:$H$35)+SUMIF($M$8:$M$35,R14,$P$8:$P$35) -> 0 | U14: Eletrônicos | W14: =SUMIF($G$11:$G$18,U14,$H$11:$H$18)+SUMIF($G$24:$G$35,U14,$H$24:$H$35)+SUMIF($N$8:$N$35,U14,$P$8:$P$35) -> 0 | X14: =IF($F$4=0,0,W14/$F$4) -> 0 | Z14: =U16 -> Uber transporte | AA14: =W16 -> 0
R15: Inter | S15: =SUMIF($F$11:$F$18,R15,$H$11:$H$18)+SUMIF($F$24:$F$35,R15,$H$24:$H$35)+SUMIF($M$8:$M$35,R15,$P$8:$P$35) -> 0 | U15: Assinaturas | W15: =SUMIF($G$11:$G$18,U15,$H$11:$H$18)+SUMIF($G$24:$G$35,U15,$H$24:$H$35)+SUMIF($N$8:$N$35,U15,$P$8:$P$35) -> 0 | X15: =IF($F$4=0,0,W15/$F$4) -> 0 | Z15: =U17 -> iFood/restaurante | AA15: =W17 -> 0
R16: Itaú | S16: =SUMIF($F$11:$F$18,R16,$H$11:$H$18)+SUMIF($F$24:$F$35,R16,$H$24:$H$35)+SUMIF($M$8:$M$35,R16,$P$8:$P$35) -> 0 | U16: Uber transporte | W16: =SUMIF($G$11:$G$18,U16,$H$11:$H$18)+SUMIF($G$24:$G$35,U16,$H$24:$H$35)+SUMIF($N$8:$N$35,U16,$P$8:$P$35) -> 0 | X16: =IF($F$4=0,0,W16/$F$4) -> 0 | Z16: =U18 -> Comida faculdade | AA16: =W18 -> 0
R17: Investimentos | S17: =S23 -> 0 | U17: iFood/restaurante | W17: =SUMIF($G$11:$G$18,U17,$H$11:$H$18)+SUMIF($G$24:$G$35,U17,$H$24:$H$35)+SUMIF($N$8:$N$35,U17,$P$8:$P$35) -> 0 | X17: =IF($F$4=0,0,W17/$F$4) -> 0 | Z17: =U19 -> Contas | AA17: =W19 -> 0
R18: Total | S18: =SUM(S13:S17) -> 0 | U18: Comida faculdade | W18: =SUMIF($G$11:$G$18,U18,$H$11:$H$18)+SUMIF($G$24:$G$35,U18,$H$24:$H$35)+SUMIF($N$8:$N$35,U18,$P$8:$P$35) -> 0 | X18: =IF($F$4=0,0,W18/$F$4) -> 0 | Z18: =U20 -> Outros | AA18: =W20 -> 0
U19: Contas | W19: =SUMIF($G$11:$G$18,U19,$H$11:$H$18)+SUMIF($G$24:$G$35,U19,$H$24:$H$35)+SUMIF($N$8:$N$35,U19,$P$8:$P$35) -> 0 | X19: =IF($F$4=0,0,W19/$F$4) -> 0
B20: Total de Parcelamentos | F20: =SUM(H24:H35) -> 0 | R20: Investimentos | U20: Outros | W20: =SUMIF($G$11:$G$18,U20,$H$11:$H$18)+SUMIF($G$24:$G$35,U20,$H$24:$H$35)+SUMIF($N$8:$N$35,U20,$P$8:$P$35) -> 0 | X20: =IF($F$4=0,0,W20/$F$4) -> 0
R21: Reserva
B22: Parcelamentos | R22: Renda fixa | U22: Gastos por tipo de pagamento
B23: Nome | D23: Parcelas | E23: Data | F23: Tipo | G23: Categoria | H23: Valor | R23: Total | S23: =SUM(S21:S22) -> 0 | U23: Tipo | V23: Valor | W23: Data | X23: Pago?
U24: Débito | V24: =S13 -> 0 | X24: ☐
U25: Nubank | V25: =S14 -> 0 | X25: ☐
U26: Inter | V26: =S15 -> 0 | X26: ☐
U27: Itaú | V27: =S16 -> 0 | X27: ☐
R30: Porcentagem de gastos por categoria

Sheet Julho
B2: Julho | Z2: Categoria | AA2: Valor gasto
R3: Saldo: | S3: =S10-S18 -> 0 | U3: Gastos do mês por categoria: | Z3: =U5 -> Mercado | AA3: =W5 -> 0
B4: Total de gastos: | F4: =F7+F20+N4 -> 0 | J4: Total de Gastos do Mês: | N4: =SUM(P8:P35) -> 0 | U4: Categoria | V4: Valor esperado | W4: Valor gasto | X4: Porcentagem | Z4: =U6 -> Despesas eventuais | AA4: =W6 -> 0
U5: Mercado | W5: =SUMIF($G$11:$G$18,U5,$H$11:$H$18)+SUMIF($G$24:$G$35,U5,$H$24:$H$35)+SUMIF($N$8:$N$35,U5,$P$8:$P$35) -> 0 | X5: =IF($F$4=0,0,W5/$F$4) -> 0 | Z5: =U7 -> Necessidades | AA5: =W7 -> 0
J6: Gastos do Mês | U6: Despesas eventuais | W6: =SUMIF($G$11:$G$18,U6,$H$11:$H$18)+SUMIF($G$24:$G$35,U6,$H$24:$H$35)+SUMIF($N$8:$N$35,U6,$P$8:$P$35) -> 0 | X6: =IF($F$4=0,0,W6/$F$4) -> 0 | Z6: =U8 -> Roupa | AA6: =W8 -> 0
B7: Total de Fixos: | F7: =SUM(H11:H18) -> 0 | J7: Nome | L7: Data | M7: Tipo | N7: Categoria | P7: Valor | R7: Entradas | U7: Necessidades | W7: =SUMIF($G$11:$G$18,U7,$H$11:$H$18)+SUMIF($G$24:$G$35,U7,$H$24:$H$35)+SUMIF($N$8:$N$35,U7,$P$8:$P$35) -> 0 | X7: =IF($F$4=0,0,W7/$F$4) -> 0 | Z7: =U9 -> Saúde | AA7: =W9 -> 0
R8: Salário | U8: Roupa | W8: =SUMIF($G$11:$G$18,U8,$H$11:$H$18)+SUMIF($G$24:$G$35,U8,$H$24:$H$35)+SUMIF($N$8:$N$35,U8,$P$8:$P$35) -> 0 | X8: =IF($F$4=0,0,W8/$F$4) -> 0 | Z8: =U10 -> Presentes | AA8: =W10 -> 0
B9: Fixos | R9: Bônus | U9: Saúde | W9: =SUMIF($G$11:$G$18,U9,$H$11:$H$18)+SUMIF($G$24:$G$35,U9,$H$24:$H$35)+SUMIF($N$8:$N$35,U9,$P$8:$P$35) -> 0 | X9: =IF($F$4=0,0,W9/$F$4) -> 0 | Z9: =U11 -> Beleza | AA9: =W11 -> 0
B10: Nome | D10: Pago? | E10: Data | F10: Tipo | G10: Categoria | H10: Valor | R10: Total | S10: =SUM(S8:S9) -> 0 | U10: Presentes | W10: =SUMIF($G$11:$G$18,U10,$H$11:$H$18)+SUMIF($G$24:$G$35,U10,$H$24:$H$35)+SUMIF($N$8:$N$35,U10,$P$8:$P$35) -> 0 | X10: =IF($F$4=0,0,W10/$F$4) -> 0 | Z10: =U12 -> Desenvolvimento | AA10: =W12 -> 0
U11: Beleza | W11: =SUMIF($G$11:$G$18,U11,$H$11:$H$18)+SUMIF($G$24:$G$35,U11,$H$24:$H$35)+SUMIF($N$8:$N$35,U11,$P$8:$P$35) -> 0 | X11: =IF($F$4=0,0,W11/$F$4) -> 0 | Z11: =U13 -> Lazer | AA11: =W13 -> 0
R12: Saídas | U12: Desenvolvimento | W12: =SUMIF($G$11:$G$18,U12,$H$11:$H$18)+SUMIF($G$24:$G$35,U12,$H$24:$H$35)+SUMIF($N$8:$N$35,U12,$P$8:$P$35) -> 0 | X12: =IF($F$4=0,0,W12/$F$4) -> 0 | Z12: =U14 -> Eletrônicos | AA12: =W14 -> 0
R13: Débito | S13: =SUMIF($F$11:$F$18,R13,$H$11:$H$18)+SUMIF($F$24:$F$35,R13,$H$24:$H$35)+SUMIF($M$8:$M$35,R13,$P$8:$P$35) -> 0 | U13: Lazer | W13: =SUMIF($G$11:$G$18,U13,$H$11:$H$18)+SUMIF($G$24:$G$35,U13,$H$24:$H$35)+SUMIF($N$8:$N$35,U13,$P$8:$P$35) -> 0 | X13: =IF($F$4=0,0,W13/$F$4) -> 0 | Z13: =U15 -> Assinaturas | AA13: =W15 -> 0
R14: Nubank | S14: =SUMIF($F$11:$F$18,R14,$H$11:$H$18)+SUMIF($F$24:$F$35,R14,$H$24:$H$35)+SUMIF($M$8:$M$35,R14,$P$8:$P$35) -> 0 | U14: Eletrônicos | W14: =SUMIF($G$11:$G$18,U14,$H$11:$H$18)+SUMIF($G$24:$G$35,U14,$H$24:$H$35)+SUMIF($N$8:$N$35,U14,$P$8:$P$35) -> 0 | X14: =IF($F$4=0,0,W14/$F$4) -> 0 | Z14: =U16 -> Uber transporte | AA14: =W16 -> 0
R15: Inter | S15: =SUMIF($F$11:$F$18,R15,$H$11:$H$18)+SUMIF($F$24:$F$35,R15,$H$24:$H$35)+SUMIF($M$8:$M$35,R15,$P$8:$P$35) -> 0 | U15: Assinaturas | W15: =SUMIF($G$11:$G$18,U15,$H$11:$H$18)+SUMIF($G$24:$G$35,U15,$H$24:$H$35)+SUMIF($N$8:$N$35,U15,$P$8:$P$35) -> 0 | X15: =IF($F$4=0,0,W15/$F$4) -> 0 | Z15: =U17 -> iFood/restaurante | AA15: =W17 -> 0
R16: Itaú | S16: =SUMIF($F$11:$F$18,R16,$H$11:$H$18)+SUMIF($F$24:$F$35,R16,$H$24:$H$35)+SUMIF($M$8:$M$35,R16,$P$8:$P$35) -> 0 | U16: Uber transporte | W16: =SUMIF($G$11:$G$18,U16,$H$11:$H$18)+SUMIF($G$24:$G$35,U16,$H$24:$H$35)+SUMIF($N$8:$N$35,U16,$P$8:$P$35) -> 0 | X16: =IF($F$4=0,0,W16/$F$4) -> 0 | Z16: =U18 -> Comida faculdade | AA16: =W18 -> 0
R17: Investimentos | S17: =S23 -> 0 | U17: iFood/restaurante | W17: =SUMIF($G$11:$G$18,U17,$H$11:$H$18)+SUMIF($G$24:$G$35,U17,$H$24:$H$35)+SUMIF($N$8:$N$35,U17,$P$8:$P$35) -> 0 | X17: =IF($F$4=0,0,W17/$F$4) -> 0 | Z17: =U19 -> Contas | AA17: =W19 -> 0
R18: Total | S18: =SUM(S13:S17) -> 0 | U18: Comida faculdade | W18: =SUMIF($G$11:$G$18,U18,$H$11:$H$18)+SUMIF($G$24:$G$35,U18,$H$24:$H$35)+SUMIF($N$8:$N$35,U18,$P$8:$P$35) -> 0 | X18: =IF($F$4=0,0,W18/$F$4) -> 0 | Z18: =U20 -> Outros | AA18: =W20 -> 0
U19: Contas | W19: =SUMIF($G$11:$G$18,U19,$H$11:$H$18)+SUMIF($G$24:$G$35,U19,$H$24:$H$35)+SUMIF($N$8:$N$35,U19,$P$8:$P$35) -> 0 | X19: =IF($F$4=0,0,W19/$F$4) -> 0
B20: Total de Parcelamentos | F20: =SUM(H24:H35) -> 0 | R20: Investimentos | U20: Outros | W20: =SUMIF($G$11:$G$18,U20,$H$11:$H$18)+SUMIF($G$24:$G$35,U20,$H$24:$H$35)+SUMIF($N$8:$N$35,U20,$P$8:$P$35) -> 0 | X20: =IF($F$4=0,0,W20/$F$4) -> 0
R21: Reserva
B22: Parcelamentos | R22: Renda fixa | U22: Gastos por tipo de pagamento
B23: Nome | D23: Parcelas | E23: Data | F23: Tipo | G23: Categoria | H23: Valor | R23: Total | S23: =SUM(S21:S22) -> 0 | U23: Tipo | V23: Valor | W23: Data | X23: Pago?
U24: Débito | V24: =S13 -> 0 | X24: ☐
U25: Nubank | V25: =S14 -> 0 | X25: ☐
U26: Inter | V26: =S15 -> 0 | X26: ☐
U27: Itaú | V27: =S16 -> 0 | X27: ☐
R30: Porcentagem de gastos por categoria

Sheet Agosto
B2: Agosto | Z2: Categoria | AA2: Valor gasto
R3: Saldo: | S3: =S10-S18 -> 184.1 | U3: Gastos do mês por categoria: | Z3: =U5 -> Mercado | AA3: =W5 -> 282
B4: Total de gastos: | F4: =F7+F20+N4 -> 1965.9 | J4: Total de Gastos do Mês: | N4: =SUM(P8:P35) -> 740.5 | U4: Categoria | V4: Valor esperado | W4: Valor gasto | X4: Porcentagem | Z4: =U6 -> Despesas eventuais | AA4: =W6 -> 0
U5: Mercado | V5: 600 | W5: =SUMIF($G$11:$G$18,U5,$H$11:$H$18)+SUMIF($G$24:$G$35,U5,$H$24:$H$35)+SUMIF($N$8:$N$35,U5,$P$8:$P$35) -> 282 | X5: =IF($F$4=0,0,W5/$F$4) -> 0.14344575 | Z5: =U7 -> Necessidades | AA5: =W7 -> 58
J6: Gastos do Mês | U6: Despesas eventuais | W6: =SUMIF($G$11:$G$18,U6,$H$11:$H$18)+SUMIF($G$24:$G$35,U6,$H$24:$H$35)+SUMIF($N$8:$N$35,U6,$P$8:$P$35) -> 0 | X6: =IF($F$4=0,0,W6/$F$4) -> 0 | Z6: =U8 -> Roupa | AA6: =W8 -> 248.5
B7: Total de Fixos: | F7: =SUM(H11:H18) -> 608.9 | J7: Nome | L7: Data | M7: Tipo | N7: Categoria | P7: Valor | R7: Entradas | U7: Necessidades | W7: =SUMIF($G$11:$G$18,U7,$H$11:$H$18)+SUMIF($G$24:$G$35,U7,$H$24:$H$35)+SUMIF($N$8:$N$35,U7,$P$8:$P$35) -> 58 | X7: =IF($F$4=0,0,W7/$F$4) -> 0.029503027 | Z7: =U9 -> Saúde | AA7: =W9 -> 158
J8: Mercado | L8: 46235 | M8: Nubank | N8: Mercado | P8: 125 | R8: Salário | S8: 2400 | U8: Roupa | V8: 100 | W8: =SUMIF($G$11:$G$18,U8,$H$11:$H$18)+SUMIF($G$24:$G$35,U8,$H$24:$H$35)+SUMIF($N$8:$N$35,U8,$P$8:$P$35) -> 248.5 | X8: =IF($F$4=0,0,W8/$F$4) -> 0.12640521 | Z8: =U10 -> Presentes | AA8: =W10 -> 0
B9: Fixos | J9: Uber | L9: 46235 | M9: Nubank | N9: Uber transporte | P9: 31 | R9: Bônus | U9: Saúde | W9: =SUMIF($G$11:$G$18,U9,$H$11:$H$18)+SUMIF($G$24:$G$35,U9,$H$24:$H$35)+SUMIF($N$8:$N$35,U9,$P$8:$P$35) -> 158 | X9: =IF($F$4=0,0,W9/$F$4) -> 0.080370314 | Z9: =U11 -> Beleza | AA9: =W11 -> 332
B10: Nome | D10: Pago? | E10: Data | F10: Tipo | G10: Categoria | H10: Valor | J10: Uber | L10: 46235 | M10: Nubank | N10: Uber transporte | P10: 25 | R10: Total | S10: =SUM(S8:S9) -> 2400 | U10: Presentes | W10: =SUMIF($G$11:$G$18,U10,$H$11:$H$18)+SUMIF($G$24:$G$35,U10,$H$24:$H$35)+SUMIF($N$8:$N$35,U10,$P$8:$P$35) -> 0 | X10: =IF($F$4=0,0,W10/$F$4) -> 0 | Z10: =U12 -> Desenvolvimento | AA10: =W12 -> 0
B11: Academia | D11: ☐ | E11: 46239 | F11: Nubank | G11: Saúde | H11: 120 | J11: Hambúrguer jantar | L11: 46236 | M11: Nubank | N11: iFood/restaurante | P11: 39 | U11: Beleza | V11: 100 | W11: =SUMIF($G$11:$G$18,U11,$H$11:$H$18)+SUMIF($G$24:$G$35,U11,$H$24:$H$35)+SUMIF($N$8:$N$35,U11,$P$8:$P$35) -> 332 | X11: =IF($F$4=0,0,W11/$F$4) -> 0.16887939 | Z11: =U13 -> Lazer | AA11: =W13 -> 0
B12: Conta de água | D12: ☐ | E12: 46240 | F12: Nubank | G12: Contas | H12: 120 | J12: Almoço trabalho | L12: 46236 | M12: Nubank | N12: iFood/restaurante | P12: 35 | R12: Saídas | U12: Desenvolvimento | W12: =SUMIF($G$11:$G$18,U12,$H$11:$H$18)+SUMIF($G$24:$G$35,U12,$H$24:$H$35)+SUMIF($N$8:$N$35,U12,$P$8:$P$35) -> 0 | X12: =IF($F$4=0,0,W12/$F$4) -> 0 | Z12: =U14 -> Eletrônicos | AA12: =W14 -> 45
B13: Internet | D13: ☐ | E13: 46241 | F13: Nubank | G13: Contas | H13: 130 | J13: Farmácia | L13: 46237 | M13: Nubank | N13: Beleza | P13: 47 | R13: Débito | S13: =SUMIF($F$11:$F$18,R13,$H$11:$H$18)+SUMIF($F$24:$F$35,R13,$H$24:$H$35)+SUMIF($M$8:$M$35,R13,$P$8:$P$35) -> 96.9 | U13: Lazer | W13: =SUMIF($G$11:$G$18,U13,$H$11:$H$18)+SUMIF($G$24:$G$35,U13,$H$24:$H$35)+SUMIF($N$8:$N$35,U13,$P$8:$P$35) -> 0 | X13: =IF($F$4=0,0,W13/$F$4) -> 0 | Z13: =U15 -> Assinaturas | AA13: =W15 -> 103.9
B14: Amazon Prime | D14: ☐ | E14: 46242 | F14: Débito | G14: Assinaturas | H14: 11.9 | J14: Café faculdade | L14: 46239 | M14: Inter | N14: Comida faculdade | P14: 15 | R14: Nubank | S14: =SUMIF($F$11:$F$18,R14,$H$11:$H$18)+SUMIF($F$24:$F$35,R14,$H$24:$H$35)+SUMIF($M$8:$M$35,R14,$P$8:$P$35) -> 1417.5 | U14: Eletrônicos | W14: =SUMIF($G$11:$G$18,U14,$H$11:$H$18)+SUMIF($G$24:$G$35,U14,$H$24:$H$35)+SUMIF($N$8:$N$35,U14,$P$8:$P$35) -> 45 | X14: =IF($F$4=0,0,W14/$F$4) -> 0.022890279 | Z14: =U16 -> Uber transporte | AA14: =W16 -> 83
B15: iCloud | D15: ☐ | E15: 46243 | F15: Nubank | G15: Assinaturas | H15: 55 | J15: Frutas | L15: 46239 | M15: Nubank | N15: Mercado | P15: 34 | R15: Inter | S15: =SUMIF($F$11:$F$18,R15,$H$11:$H$18)+SUMIF($F$24:$F$35,R15,$H$24:$H$35)+SUMIF($M$8:$M$35,R15,$P$8:$P$35) -> 289.5 | U15: Assinaturas | W15: =SUMIF($G$11:$G$18,U15,$H$11:$H$18)+SUMIF($G$24:$G$35,U15,$H$24:$H$35)+SUMIF($N$8:$N$35,U15,$P$8:$P$35) -> 103.9 | X15: =IF($F$4=0,0,W15/$F$4) -> 0.052851111 | Z15: =U17 -> iFood/restaurante | AA15: =W17 -> 222.5
B16: Conta de luz | D16: ☐ | E16: 46244 | F16: Nubank | G16: Contas | H16: 135 | J16: Adicional Claro | L16: 46240 | M16: Débito | N16: Necessidades | P16: 20 | R16: Itaú | S16: =SUMIF($F$11:$F$18,R16,$H$11:$H$18)+SUMIF($F$24:$F$35,R16,$H$24:$H$35)+SUMIF($M$8:$M$35,R16,$P$8:$P$35) -> 162 | U16: Uber transporte | V16: 150 | W16: =SUMIF($G$11:$G$18,U16,$H$11:$H$18)+SUMIF($G$24:$G$35,U16,$H$24:$H$35)+SUMIF($N$8:$N$35,U16,$P$8:$P$35) -> 83 | X16: =IF($F$4=0,0,W16/$F$4) -> 0.042219848 | Z16: =U18 -> Comida faculdade | AA16: =W18 -> 48
B17: Spotify | D17: ☐ | E17: 46244 | F17: Nubank | G17: Assinaturas | H17: 12 | J17: iFood jantar | L17: 46240 | M17: Nubank | N17: iFood/restaurante | P17: 42 | R17: Investimentos | S17: =S23 -> 250 | U17: iFood/restaurante | V17: 150 | W17: =SUMIF($G$11:$G$18,U17,$H$11:$H$18)+SUMIF($G$24:$G$35,U17,$H$24:$H$35)+SUMIF($N$8:$N$35,U17,$P$8:$P$35) -> 222.5 | X17: =IF($F$4=0,0,W17/$F$4) -> 0.11317971 | Z17: =U19 -> Contas | AA17: =W19 -> 385
B18: Reservatório de Dopamina | D18: ☐ | E18: 46246 | F18: Nubank | G18: Assinaturas | H18: 25 | J18: Uber trabalho | L18: 46241 | M18: Nubank | N18: Uber transporte | P18: 27 | R18: Total | S18: =SUM(S13:S17) -> 2215.9 | U18: Comida faculdade | V18: 40 | W18: =SUMIF($G$11:$G$18,U18,$H$11:$H$18)+SUMIF($G$24:$G$35,U18,$H$24:$H$35)+SUMIF($N$8:$N$35,U18,$P$8:$P$35) -> 48 | X18: =IF($F$4=0,0,W18/$F$4) -> 0.024416298 | Z18: =U20 -> Outros | AA18: =W20 -> 0
J19: Café faculdade | L19: 46242 | M19: Nubank | N19: Comida faculdade | P19: 10 | U19: Contas | W19: =SUMIF($G$11:$G$18,U19,$H$11:$H$18)+SUMIF($G$24:$G$35,U19,$H$24:$H$35)+SUMIF($N$8:$N$35,U19,$P$8:$P$35) -> 385 | X19: =IF($F$4=0,0,W19/$F$4) -> 0.19583906
B20: Total de Parcelamentos | F20: =SUM(H24:H35) -> 616.5 | J20: Mercado | L20: 46243 | M20: Nubank | N20: Mercado | P20: 65 | R20: Investimentos | U20: Outros | W20: =SUMIF($G$11:$G$18,U20,$H$11:$H$18)+SUMIF($G$24:$G$35,U20,$H$24:$H$35)+SUMIF($N$8:$N$35,U20,$P$8:$P$35) -> 0 | X20: =IF($F$4=0,0,W20/$F$4) -> 0
J21: Jantar poke | L21: 46244 | M21: Débito | N21: iFood/restaurante | P21: 65 | R21: Reserva | S21: 150
B22: Parcelamentos | J22: Restrição alérgica | L22: 46245 | M22: Nubank | N22: Saúde | P22: 38 | R22: Renda fixa | S22: 100 | U22: Gastos por tipo de pagamento
B23: Nome | D23: Parcelas | E23: Data | F23: Tipo | G23: Categoria | H23: Valor | J23: Café faculdade | L23: 46246 | M23: Nubank | N23: Comida faculdade | P23: 8 | R23: Total | S23: =SUM(S21:S22) -> 250 | U23: Tipo | V23: Valor | W23: Data | X23: Pago?
B24: Depilação a laser | D24: 5/12 | E24: 46137 | F24: Nubank | G24: Beleza | H24: 105 | J24: Mercado | L24: 46247 | M24: Nubank | N24: Mercado | P24: 58 | U24: Débito | V24: =S13 -> 96.9 | W24: 46266 | X24: ☐
B25: Fone de ouvido | D25: 5/5 | E25: 46124 | F25: Itaú | G25: Eletrônicos | H25: 45 | J25: Almoço delivery | L25: 46249 | M25: Nubank | N25: iFood/restaurante | P25: 41.5 | U25: Nubank | V25: =S14 -> 1417.5 | W25: 46267 | X25: ☐
B26: Roupa de treino | D26: 4/4 | E26: 46167 | F26: Nubank | G26: Roupa | H26: 37 | J26: Pão e café | L26: 46250 | M26: Nubank | N26: Comida faculdade | P26: 15 | U26: Inter | V26: =S15 -> 289.5 | W26: 46268 | X26: ☐
B27: Maquiagem Oceane | D27: 3/3 | E27: 46190 | F27: Itaú | G27: Beleza | H27: 42 | U27: Itaú | V27: =S16 -> 162 | W27: 46269 | X27: ☐
B28: Escova de cabelo | D28: 2/2 | E28: 46206 | F28: Inter | G28: Beleza | H28: 63
B29: Vestido | D29: 2/3 | E29: 46211 | F29: Inter | G29: Roupa | H29: 69
B30: Blush Sheglam | D30: 2/3 | E30: 46212 | F30: Itaú | G30: Beleza | H30: 75 | R30: Porcentagem de gastos por categoria
B31: Tênis esporte | D31: 2/6 | E31: 46213 | F31: Inter | G31: Roupa | H31: 75
B32: Roupa viagem | D32: 2/3 | E32: 46213 | F32: Inter | G32: Roupa | H32: 67.5
B33: Itens Shopee | D33: 1/3 | E33: 46215 | F33: Nubank | G33: Necessidades | H33: 38

Sheet Setembro
B2: Setembro | Z2: Categoria | AA2: Valor gasto
R3: Saldo: | S3: =S10-S18 -> 1400 | U3: Gastos do mês por categoria: | Z3: =U5 -> Mercado | AA3: =W5 -> 0
B4: Total de gastos: | F4: =F7+F20+N4 -> 300 | J4: Total de Gastos do Mês: | N4: =SUM(P8:P35) -> 0 | U4: Categoria | V4: Valor esperado | W4: Valor gasto | X4: Porcentagem | Z4: =U6 -> Despesas eventuais | AA4: =W6 -> 0
U5: Mercado | W5: =SUMIF($G$11:$G$18,U5,$H$11:$H$18)+SUMIF($G$24:$G$35,U5,$H$24:$H$35)+SUMIF($N$8:$N$35,U5,$P$8:$P$35) -> 0 | X5: =IF($F$4=0,0,W5/$F$4) -> 0 | Z5: =U7 -> Necessidades | AA5: =W7 -> 130
J6: Gastos do Mês | U6: Despesas eventuais | W6: =SUMIF($G$11:$G$18,U6,$H$11:$H$18)+SUMIF($G$24:$G$35,U6,$H$24:$H$35)+SUMIF($N$8:$N$35,U6,$P$8:$P$35) -> 0 | X6: =IF($F$4=0,0,W6/$F$4) -> 0 | Z6: =U8 -> Roupa | AA6: =W8 -> 0
B7: Total de Fixos: | F7: =SUM(H11:H18) -> 300 | J7: Nome | L7: Data | M7: Tipo | N7: Categoria | P7: Valor | R7: Entradas | U7: Necessidades | W7: =SUMIF($G$11:$G$18,U7,$H$11:$H$18)+SUMIF($G$24:$G$35,U7,$H$24:$H$35)+SUMIF($N$8:$N$35,U7,$P$8:$P$35) -> 130 | X7: =IF($F$4=0,0,W7/$F$4) -> 0.43333333 | Z7: =U9 -> Saúde | AA7: =W9 -> 0
R8: Salário | S8: 2500 | U8: Roupa | W8: =SUMIF($G$11:$G$18,U8,$H$11:$H$18)+SUMIF($G$24:$G$35,U8,$H$24:$H$35)+SUMIF($N$8:$N$35,U8,$P$8:$P$35) -> 0 | X8: =IF($F$4=0,0,W8/$F$4) -> 0 | Z8: =U10 -> Presentes | AA8: =W10 -> 0
B9: Fixos | R9: Bônus | S9: 0 | U9: Saúde | W9: =SUMIF($G$11:$G$18,U9,$H$11:$H$18)+SUMIF($G$24:$G$35,U9,$H$24:$H$35)+SUMIF($N$8:$N$35,U9,$P$8:$P$35) -> 0 | X9: =IF($F$4=0,0,W9/$F$4) -> 0 | Z9: =U11 -> Beleza | AA9: =W11 -> 0
B10: Nome | D10: Pago? | E10: Data | F10: Tipo | G10: Categoria | H10: Valor | R10: Total | S10: =SUM(S8:S9) -> 2500 | U10: Presentes | W10: =SUMIF($G$11:$G$18,U10,$H$11:$H$18)+SUMIF($G$24:$G$35,U10,$H$24:$H$35)+SUMIF($N$8:$N$35,U10,$P$8:$P$35) -> 0 | X10: =IF($F$4=0,0,W10/$F$4) -> 0 | Z10: =U12 -> Desenvolvimento | AA10: =W12 -> 170
B11: Internet | D11: ☐ | E11: 46249 | F11: Débito | G11: Necessidades | H11: 130 | U11: Beleza | W11: =SUMIF($G$11:$G$18,U11,$H$11:$H$18)+SUMIF($G$24:$G$35,U11,$H$24:$H$35)+SUMIF($N$8:$N$35,U11,$P$8:$P$35) -> 0 | X11: =IF($F$4=0,0,W11/$F$4) -> 0 | Z11: =U13 -> Lazer | AA11: =W13 -> 0
B12: Faculdade | D12: ☐ | E12: 46259 | F12: Débito | G12: Desenvolvimento | H12: 170 | R12: Saídas | U12: Desenvolvimento | W12: =SUMIF($G$11:$G$18,U12,$H$11:$H$18)+SUMIF($G$24:$G$35,U12,$H$24:$H$35)+SUMIF($N$8:$N$35,U12,$P$8:$P$35) -> 170 | X12: =IF($F$4=0,0,W12/$F$4) -> 0.56666667 | Z12: =U14 -> Eletrônicos | AA12: =W14 -> 0
B13: Fatura Cartão | D13: ☐ | E13: 11 | R13: Débito | S13: =SUMIF($F$11:$F$18,R13,$H$11:$H$18)+SUMIF($F$24:$F$35,R13,$H$24:$H$35)+SUMIF($M$8:$M$35,R13,$P$8:$P$35) -> 300 | U13: Lazer | W13: =SUMIF($G$11:$G$18,U13,$H$11:$H$18)+SUMIF($G$24:$G$35,U13,$H$24:$H$35)+SUMIF($N$8:$N$35,U13,$P$8:$P$35) -> 0 | X13: =IF($F$4=0,0,W13/$F$4) -> 0 | Z13: =U15 -> Assinaturas | AA13: =W15 -> 0
R14: Nubank | S14: =SUMIF($F$11:$F$18,R14,$H$11:$H$18)+SUMIF($F$24:$F$35,R14,$H$24:$H$35)+SUMIF($M$8:$M$35,R14,$P$8:$P$35) -> 0 | U14: Eletrônicos | W14: =SUMIF($G$11:$G$18,U14,$H$11:$H$18)+SUMIF($G$24:$G$35,U14,$H$24:$H$35)+SUMIF($N$8:$N$35,U14,$P$8:$P$35) -> 0 | X14: =IF($F$4=0,0,W14/$F$4) -> 0 | Z14: =U16 -> Uber transporte | AA14: =W16 -> 0
R15: Inter | S15: =SUMIF($F$11:$F$18,R15,$H$11:$H$18)+SUMIF($F$24:$F$35,R15,$H$24:$H$35)+SUMIF($M$8:$M$35,R15,$P$8:$P$35) -> 0 | U15: Assinaturas | W15: =SUMIF($G$11:$G$18,U15,$H$11:$H$18)+SUMIF($G$24:$G$35,U15,$H$24:$H$35)+SUMIF($N$8:$N$35,U15,$P$8:$P$35) -> 0 | X15: =IF($F$4=0,0,W15/$F$4) -> 0 | Z15: =U17 -> iFood/restaurante | AA15: =W17 -> 0
R16: Itaú | S16: =SUMIF($F$11:$F$18,R16,$H$11:$H$18)+SUMIF($F$24:$F$35,R16,$H$24:$H$35)+SUMIF($M$8:$M$35,R16,$P$8:$P$35) -> 0 | U16: Uber transporte | W16: =SUMIF($G$11:$G$18,U16,$H$11:$H$18)+SUMIF($G$24:$G$35,U16,$H$24:$H$35)+SUMIF($N$8:$N$35,U16,$P$8:$P$35) -> 0 | X16: =IF($F$4=0,0,W16/$F$4) -> 0 | Z16: =U18 -> Comida faculdade | AA16: =W18 -> 0
R17: Investimentos | S17: =S23 -> 800 | U17: iFood/restaurante | W17: =SUMIF($G$11:$G$18,U17,$H$11:$H$18)+SUMIF($G$24:$G$35,U17,$H$24:$H$35)+SUMIF($N$8:$N$35,U17,$P$8:$P$35) -> 0 | X17: =IF($F$4=0,0,W17/$F$4) -> 0 | Z17: =U19 -> Contas | AA17: =W19 -> 0
R18: Total | S18: =SUM(S13:S17) -> 1100 | U18: Comida faculdade | W18: =SUMIF($G$11:$G$18,U18,$H$11:$H$18)+SUMIF($G$24:$G$35,U18,$H$24:$H$35)+SUMIF($N$8:$N$35,U18,$P$8:$P$35) -> 0 | X18: =IF($F$4=0,0,W18/$F$4) -> 0 | Z18: =U20 -> Outros | AA18: =W20 -> 0
U19: Contas | W19: =SUMIF($G$11:$G$18,U19,$H$11:$H$18)+SUMIF($G$24:$G$35,U19,$H$24:$H$35)+SUMIF($N$8:$N$35,U19,$P$8:$P$35) -> 0 | X19: =IF($F$4=0,0,W19/$F$4) -> 0
B20: Total de Parcelamentos | F20: =SUM(H24:H35) -> 0 | R20: Investimentos | U20: Outros | W20: =SUMIF($G$11:$G$18,U20,$H$11:$H$18)+SUMIF($G$24:$G$35,U20,$H$24:$H$35)+SUMIF($N$8:$N$35,U20,$P$8:$P$35) -> 0 | X20: =IF($F$4=0,0,W20/$F$4) -> 0
R21: Reserva | S21: 800
B22: Parcelamentos | R22: Renda fixa | U22: Gastos por tipo de pagamento
B23: Nome | D23: Parcelas | E23: Data | F23: Tipo | G23: Categoria | H23: Valor | R23: Total | S23: =SUM(S21:S22) -> 800 | U23: Tipo | V23: Valor | W23: Data | X23: Pago?
U24: Débito | V24: =S13 -> 300 | X24: ☐
U25: Nubank | V25: =S14 -> 0 | X25: ☐
U26: Inter | V26: =S15 -> 0 | X26: ☐
U27: Itaú | V27: =S16 -> 0 | X27: ☐
R30: Porcentagem de gastos por categoria

Sheet Outubro
B2: Outubro | Z2: Categoria | AA2: Valor gasto
R3: Saldo: | S3: =S10-S18 -> 0 | U3: Gastos do mês por categoria: | Z3: =U5 -> Mercado | AA3: =W5 -> 0
B4: Total de gastos: | F4: =F7+F20+N4 -> 0 | J4: Total de Gastos do Mês: | N4: =SUM(P8:P35) -> 0 | U4: Categoria | V4: Valor esperado | W4: Valor gasto | X4: Porcentagem | Z4: =U6 -> Despesas eventuais | AA4: =W6 -> 0
U5: Mercado | W5: =SUMIF($G$11:$G$18,U5,$H$11:$H$18)+SUMIF($G$24:$G$35,U5,$H$24:$H$35)+SUMIF($N$8:$N$35,U5,$P$8:$P$35) -> 0 | X5: =IF($F$4=0,0,W5/$F$4) -> 0 | Z5: =U7 -> Necessidades | AA5: =W7 -> 0
J6: Gastos do Mês | U6: Despesas eventuais | W6: =SUMIF($G$11:$G$18,U6,$H$11:$H$18)+SUMIF($G$24:$G$35,U6,$H$24:$H$35)+SUMIF($N$8:$N$35,U6,$P$8:$P$35) -> 0 | X6: =IF($F$4=0,0,W6/$F$4) -> 0 | Z6: =U8 -> Roupa | AA6: =W8 -> 0
B7: Total de Fixos: | F7: =SUM(H11:H18) -> 0 | J7: Nome | L7: Data | M7: Tipo | N7: Categoria | P7: Valor | R7: Entradas | U7: Necessidades | W7: =SUMIF($G$11:$G$18,U7,$H$11:$H$18)+SUMIF($G$24:$G$35,U7,$H$24:$H$35)+SUMIF($N$8:$N$35,U7,$P$8:$P$35) -> 0 | X7: =IF($F$4=0,0,W7/$F$4) -> 0 | Z7: =U9 -> Saúde | AA7: =W9 -> 0
R8: Salário | U8: Roupa | W8: =SUMIF($G$11:$G$18,U8,$H$11:$H$18)+SUMIF($G$24:$G$35,U8,$H$24:$H$35)+SUMIF($N$8:$N$35,U8,$P$8:$P$35) -> 0 | X8: =IF($F$4=0,0,W8/$F$4) -> 0 | Z8: =U10 -> Presentes | AA8: =W10 -> 0
B9: Fixos | R9: Bônus | U9: Saúde | W9: =SUMIF($G$11:$G$18,U9,$H$11:$H$18)+SUMIF($G$24:$G$35,U9,$H$24:$H$35)+SUMIF($N$8:$N$35,U9,$P$8:$P$35) -> 0 | X9: =IF($F$4=0,0,W9/$F$4) -> 0 | Z9: =U11 -> Beleza | AA9: =W11 -> 0
B10: Nome | D10: Pago? | E10: Data | F10: Tipo | G10: Categoria | H10: Valor | R10: Total | S10: =SUM(S8:S9) -> 0 | U10: Presentes | W10: =SUMIF($G$11:$G$18,U10,$H$11:$H$18)+SUMIF($G$24:$G$35,U10,$H$24:$H$35)+SUMIF($N$8:$N$35,U10,$P$8:$P$35) -> 0 | X10: =IF($F$4=0,0,W10/$F$4) -> 0 | Z10: =U12 -> Desenvolvimento | AA10: =W12 -> 0
U11: Beleza | W11: =SUMIF($G$11:$G$18,U11,$H$11:$H$18)+SUMIF($G$24:$G$35,U11,$H$24:$H$35)+SUMIF($N$8:$N$35,U11,$P$8:$P$35) -> 0 | X11: =IF($F$4=0,0,W11/$F$4) -> 0 | Z11: =U13 -> Lazer | AA11: =W13 -> 0
R12: Saídas | U12: Desenvolvimento | W12: =SUMIF($G$11:$G$18,U12,$H$11:$H$18)+SUMIF($G$24:$G$35,U12,$H$24:$H$35)+SUMIF($N$8:$N$35,U12,$P$8:$P$35) -> 0 | X12: =IF($F$4=0,0,W12/$F$4) -> 0 | Z12: =U14 -> Eletrônicos | AA12: =W14 -> 0
R13: Débito | S13: =SUMIF($F$11:$F$18,R13,$H$11:$H$18)+SUMIF($F$24:$F$35,R13,$H$24:$H$35)+SUMIF($M$8:$M$35,R13,$P$8:$P$35) -> 0 | U13: Lazer | W13: =SUMIF($G$11:$G$18,U13,$H$11:$H$18)+SUMIF($G$24:$G$35,U13,$H$24:$H$35)+SUMIF($N$8:$N$35,U13,$P$8:$P$35) -> 0 | X13: =IF($F$4=0,0,W13/$F$4) -> 0 | Z13: =U15 -> Assinaturas | AA13: =W15 -> 0
R14: Nubank | S14: =SUMIF($F$11:$F$18,R14,$H$11:$H$18)+SUMIF($F$24:$F$35,R14,$H$24:$H$35)+SUMIF($M$8:$M$35,R14,$P$8:$P$35) -> 0 | U14: Eletrônicos | W14: =SUMIF($G$11:$G$18,U14,$H$11:$H$18)+SUMIF($G$24:$G$35,U14,$H$24:$H$35)+SUMIF($N$8:$N$35,U14,$P$8:$P$35) -> 0 | X14: =IF($F$4=0,0,W14/$F$4) -> 0 | Z14: =U16 -> Uber transporte | AA14: =W16 -> 0
R15: Inter | S15: =SUMIF($F$11:$F$18,R15,$H$11:$H$18)+SUMIF($F$24:$F$35,R15,$H$24:$H$35)+SUMIF($M$8:$M$35,R15,$P$8:$P$35) -> 0 | U15: Assinaturas | W15: =SUMIF($G$11:$G$18,U15,$H$11:$H$18)+SUMIF($G$24:$G$35,U15,$H$24:$H$35)+SUMIF($N$8:$N$35,U15,$P$8:$P$35) -> 0 | X15: =IF($F$4=0,0,W15/$F$4) -> 0 | Z15: =U17 -> iFood/restaurante | AA15: =W17 -> 0
R16: Itaú | S16: =SUMIF($F$11:$F$18,R16,$H$11:$H$18)+SUMIF($F$24:$F$35,R16,$H$24:$H$35)+SUMIF($M$8:$M$35,R16,$P$8:$P$35) -> 0 | U16: Uber transporte | W16: =SUMIF($G$11:$G$18,U16,$H$11:$H$18)+SUMIF($G$24:$G$35,U16,$H$24:$H$35)+SUMIF($N$8:$N$35,U16,$P$8:$P$35) -> 0 | X16: =IF($F$4=0,0,W16/$F$4) -> 0 | Z16: =U18 -> Comida faculdade | AA16: =W18 -> 0
R17: Investimentos | S17: =S23 -> 0 | U17: iFood/restaurante | W17: =SUMIF($G$11:$G$18,U17,$H$11:$H$18)+SUMIF($G$24:$G$35,U17,$H$24:$H$35)+SUMIF($N$8:$N$35,U17,$P$8:$P$35) -> 0 | X17: =IF($F$4=0,0,W17/$F$4) -> 0 | Z17: =U19 -> Contas | AA17: =W19 -> 0
R18: Total | S18: =SUM(S13:S17) -> 0 | U18: Comida faculdade | W18: =SUMIF($G$11:$G$18,U18,$H$11:$H$18)+SUMIF($G$24:$G$35,U18,$H$24:$H$35)+SUMIF($N$8:$N$35,U18,$P$8:$P$35) -> 0 | X18: =IF($F$4=0,0,W18/$F$4) -> 0 | Z18: =U20 -> Outros | AA18: =W20 -> 0
U19: Contas | W19: =SUMIF($G$11:$G$18,U19,$H$11:$H$18)+SUMIF($G$24:$G$35,U19,$H$24:$H$35)+SUMIF($N$8:$N$35,U19,$P$8:$P$35) -> 0 | X19: =IF($F$4=0,0,W19/$F$4) -> 0
B20: Total de Parcelamentos | F20: =SUM(H24:H35) -> 0 | R20: Investimentos | U20: Outros | W20: =SUMIF($G$11:$G$18,U20,$H$11:$H$18)+SUMIF($G$24:$G$35,U20,$H$24:$H$35)+SUMIF($N$8:$N$35,U20,$P$8:$P$35) -> 0 | X20: =IF($F$4=0,0,W20/$F$4) -> 0
R21: Reserva
B22: Parcelamentos | R22: Renda fixa | U22: Gastos por tipo de pagamento
B23: Nome | D23: Parcelas | E23: Data | F23: Tipo | G23: Categoria | H23: Valor | R23: Total | S23: =SUM(S21:S22) -> 0 | U23: Tipo | V23: Valor | W23: Data | X23: Pago?
U24: Débito | V24: =S13 -> 0 | X24: ☐
U25: Nubank | V25: =S14 -> 0 | X25: ☐
U26: Inter | V26: =S15 -> 0 | X26: ☐
U27: Itaú | V27: =S16 -> 0 | X27: ☐
R30: Porcentagem de gastos por categoria

Sheet Novembro
B2: Novembro | Z2: Categoria | AA2: Valor gasto
R3: Saldo: | S3: =S10-S18 -> 0 | U3: Gastos do mês por categoria: | Z3: =U5 -> Mercado | AA3: =W5 -> 0
B4: Total de gastos: | F4: =F7+F20+N4 -> 0 | J4: Total de Gastos do Mês: | N4: =SUM(P8:P35) -> 0 | U4: Categoria | V4: Valor esperado | W4: Valor gasto | X4: Porcentagem | Z4: =U6 -> Despesas eventuais | AA4: =W6 -> 0
U5: Mercado | W5: =SUMIF($G$11:$G$18,U5,$H$11:$H$18)+SUMIF($G$24:$G$35,U5,$H$24:$H$35)+SUMIF($N$8:$N$35,U5,$P$8:$P$35) -> 0 | X5: =IF($F$4=0,0,W5/$F$4) -> 0 | Z5: =U7 -> Necessidades | AA5: =W7 -> 0
J6: Gastos do Mês | U6: Despesas eventuais | W6: =SUMIF($G$11:$G$18,U6,$H$11:$H$18)+SUMIF($G$24:$G$35,U6,$H$24:$H$35)+SUMIF($N$8:$N$35,U6,$P$8:$P$35) -> 0 | X6: =IF($F$4=0,0,W6/$F$4) -> 0 | Z6: =U8 -> Roupa | AA6: =W8 -> 0
B7: Total de Fixos: | F7: =SUM(H11:H18) -> 0 | J7: Nome | L7: Data | M7: Tipo | N7: Categoria | P7: Valor | R7: Entradas | U7: Necessidades | W7: =SUMIF($G$11:$G$18,U7,$H$11:$H$18)+SUMIF($G$24:$G$35,U7,$H$24:$H$35)+SUMIF($N$8:$N$35,U7,$P$8:$P$35) -> 0 | X7: =IF($F$4=0,0,W7/$F$4) -> 0 | Z7: =U9 -> Saúde | AA7: =W9 -> 0
R8: Salário | U8: Roupa | W8: =SUMIF($G$11:$G$18,U8,$H$11:$H$18)+SUMIF($G$24:$G$35,U8,$H$24:$H$35)+SUMIF($N$8:$N$35,U8,$P$8:$P$35) -> 0 | X8: =IF($F$4=0,0,W8/$F$4) -> 0 | Z8: =U10 -> Presentes | AA8: =W10 -> 0
B9: Fixos | R9: Bônus | U9: Saúde | W9: =SUMIF($G$11:$G$18,U9,$H$11:$H$18)+SUMIF($G$24:$G$35,U9,$H$24:$H$35)+SUMIF($N$8:$N$35,U9,$P$8:$P$35) -> 0 | X9: =IF($F$4=0,0,W9/$F$4) -> 0 | Z9: =U11 -> Beleza | AA9: =W11 -> 0
B10: Nome | D10: Pago? | E10: Data | F10: Tipo | G10: Categoria | H10: Valor | R10: Total | S10: =SUM(S8:S9) -> 0 | U10: Presentes | W10: =SUMIF($G$11:$G$18,U10,$H$11:$H$18)+SUMIF($G$24:$G$35,U10,$H$24:$H$35)+SUMIF($N$8:$N$35,U10,$P$8:$P$35) -> 0 | X10: =IF($F$4=0,0,W10/$F$4) -> 0 | Z10: =U12 -> Desenvolvimento | AA10: =W12 -> 0
U11: Beleza | W11: =SUMIF($G$11:$G$18,U11,$H$11:$H$18)+SUMIF($G$24:$G$35,U11,$H$24:$H$35)+SUMIF($N$8:$N$35,U11,$P$8:$P$35) -> 0 | X11: =IF($F$4=0,0,W11/$F$4) -> 0 | Z11: =U13 -> Lazer | AA11: =W13 -> 0
R12: Saídas | U12: Desenvolvimento | W12: =SUMIF($G$11:$G$18,U12,$H$11:$H$18)+SUMIF($G$24:$G$35,U12,$H$24:$H$35)+SUMIF($N$8:$N$35,U12,$P$8:$P$35) -> 0 | X12: =IF($F$4=0,0,W12/$F$4) -> 0 | Z12: =U14 -> Eletrônicos | AA12: =W14 -> 0
R13: Débito | S13: =SUMIF($F$11:$F$18,R13,$H$11:$H$18)+SUMIF($F$24:$F$35,R13,$H$24:$H$35)+SUMIF($M$8:$M$35,R13,$P$8:$P$35) -> 0 | U13: Lazer | W13: =SUMIF($G$11:$G$18,U13,$H$11:$H$18)+SUMIF($G$24:$G$35,U13,$H$24:$H$35)+SUMIF($N$8:$N$35,U13,$P$8:$P$35) -> 0 | X13: =IF($F$4=0,0,W13/$F$4) -> 0 | Z13: =U15 -> Assinaturas | AA13: =W15 -> 0
R14: Nubank | S14: =SUMIF($F$11:$F$18,R14,$H$11:$H$18)+SUMIF($F$24:$F$35,R14,$H$24:$H$35)+SUMIF($M$8:$M$35,R14,$P$8:$P$35) -> 0 | U14: Eletrônicos | W14: =SUMIF($G$11:$G$18,U14,$H$11:$H$18)+SUMIF($G$24:$G$35,U14,$H$24:$H$35)+SUMIF($N$8:$N$35,U14,$P$8:$P$35) -> 0 | X14: =IF($F$4=0,0,W14/$F$4) -> 0 | Z14: =U16 -> Uber transporte | AA14: =W16 -> 0
R15: Inter | S15: =SUMIF($F$11:$F$18,R15,$H$11:$H$18)+SUMIF($F$24:$F$35,R15,$H$24:$H$35)+SUMIF($M$8:$M$35,R15,$P$8:$P$35) -> 0 | U15: Assinaturas | W15: =SUMIF($G$11:$G$18,U15,$H$11:$H$18)+SUMIF($G$24:$G$35,U15,$H$24:$H$35)+SUMIF($N$8:$N$35,U15,$P$8:$P$35) -> 0 | X15: =IF($F$4=0,0,W15/$F$4) -> 0 | Z15: =U17 -> iFood/restaurante | AA15: =W17 -> 0
R16: Itaú | S16: =SUMIF($F$11:$F$18,R16,$H$11:$H$18)+SUMIF($F$24:$F$35,R16,$H$24:$H$35)+SUMIF($M$8:$M$35,R16,$P$8:$P$35) -> 0 | U16: Uber transporte | W16: =SUMIF($G$11:$G$18,U16,$H$11:$H$18)+SUMIF($G$24:$G$35,U16,$H$24:$H$35)+SUMIF($N$8:$N$35,U16,$P$8:$P$35) -> 0 | X16: =IF($F$4=0,0,W16/$F$4) -> 0 | Z16: =U18 -> Comida faculdade | AA16: =W18 -> 0
R17: Investimentos | S17: =S23 -> 0 | U17: iFood/restaurante | W17: =SUMIF($G$11:$G$18,U17,$H$11:$H$18)+SUMIF($G$24:$G$35,U17,$H$24:$H$35)+SUMIF($N$8:$N$35,U17,$P$8:$P$35) -> 0 | X17: =IF($F$4=0,0,W17/$F$4) -> 0 | Z17: =U19 -> Contas | AA17: =W19 -> 0
R18: Total | S18: =SUM(S13:S17) -> 0 | U18: Comida faculdade | W18: =SUMIF($G$11:$G$18,U18,$H$11:$H$18)+SUMIF($G$24:$G$35,U18,$H$24:$H$35)+SUMIF($N$8:$N$35,U18,$P$8:$P$35) -> 0 | X18: =IF($F$4=0,0,W18/$F$4) -> 0 | Z18: =U20 -> Outros | AA18: =W20 -> 0
U19: Contas | W19: =SUMIF($G$11:$G$18,U19,$H$11:$H$18)+SUMIF($G$24:$G$35,U19,$H$24:$H$35)+SUMIF($N$8:$N$35,U19,$P$8:$P$35) -> 0 | X19: =IF($F$4=0,0,W19/$F$4) -> 0
B20: Total de Parcelamentos | F20: =SUM(H24:H35) -> 0 | R20: Investimentos | U20: Outros | W20: =SUMIF($G$11:$G$18,U20,$H$11:$H$18)+SUMIF($G$24:$G$35,U20,$H$24:$H$35)+SUMIF($N$8:$N$35,U20,$P$8:$P$35) -> 0 | X20: =IF($F$4=0,0,W20/$F$4) -> 0
R21: Reserva
B22: Parcelamentos | R22: Renda fixa | U22: Gastos por tipo de pagamento
B23: Nome | D23: Parcelas | E23: Data | F23: Tipo | G23: Categoria | H23: Valor | R23: Total | S23: =SUM(S21:S22) -> 0 | U23: Tipo | V23: Valor | W23: Data | X23: Pago?
U24: Débito | V24: =S13 -> 0 | X24: ☐
U25: Nubank | V25: =S14 -> 0 | X25: ☐
U26: Inter | V26: =S15 -> 0 | X26: ☐
U27: Itaú | V27: =S16 -> 0 | X27: ☐
R30: Porcentagem de gastos por categoria

Sheet Dezembro
B2: Dezembro | Z2: Categoria | AA2: Valor gasto
R3: Saldo: | S3: =S10-S18 -> 0 | U3: Gastos do mês por categoria: | Z3: =U5 -> Mercado | AA3: =W5 -> 0
B4: Total de gastos: | F4: =F7+F20+N4 -> 0 | J4: Total de Gastos do Mês: | N4: =SUM(P8:P35) -> 0 | U4: Categoria | V4: Valor esperado | W4: Valor gasto | X4: Porcentagem | Z4: =U6 -> Despesas eventuais | AA4: =W6 -> 0
U5: Mercado | W5: =SUMIF($G$11:$G$18,U5,$H$11:$H$18)+SUMIF($G$24:$G$35,U5,$H$24:$H$35)+SUMIF($N$8:$N$35,U5,$P$8:$P$35) -> 0 | X5: =IF($F$4=0,0,W5/$F$4) -> 0 | Z5: =U7 -> Necessidades | AA5: =W7 -> 0
J6: Gastos do Mês | U6: Despesas eventuais | W6: =SUMIF($G$11:$G$18,U6,$H$11:$H$18)+SUMIF($G$24:$G$35,U6,$H$24:$H$35)+SUMIF($N$8:$N$35,U6,$P$8:$P$35) -> 0 | X6: =IF($F$4=0,0,W6/$F$4) -> 0 | Z6: =U8 -> Roupa | AA6: =W8 -> 0
